Fail to get yarn configuration. /home/naglemi/miniconda3/envs/mwas/lib/python3.11/site-packages/jupyterlab/staging/yarn.js:4
(()=>{var Qge=Object.create;var AS=Object.defineProperty;var bge=Object.getOwnPropertyDescriptor;var Sge=Object.getOwnPropertyNames;var vge=Object.getPrototypeOf,xge=Object.prototype.hasOwnProperty;var J=(r=>typeof require<"u"?require:typeof Proxy<"u"?new Proxy(r,{get:(e,t)=>(typeof require<"u"?require:e)[t]}):r)(function(r){if(typeof require<"u")return require.apply(this,arguments);throw new Error('Dynamic require of "'+r+'" is not supported')});var Pge=(r,e)=>()=>(r&&(e=r(r=0)),e);var w=(r,e)=>()=>(e||r((e={exports:{}}).exports,e),e.exports),ut=(r,e)=>{for(var t in e)AS(r,t,{get:e[t],enumerable:!0})},Dge=(r,e,t,i)=>{if(e&&typeof e=="object"||typeof e=="function")for(let n of Sge(e))!xge.call(r,n)&&n!==t&&AS(r,n,{get:()=>e[n],enumerable:!(i=bge(e,n))||i.enumerable});return r};var Pe=(r,e,t)=>(t=r!=null?Qge(vge(r)):{},Dge(e||!r||!r.__esModule?AS(t,"default",{value:r,enumerable:!0}):t,r));var QK=w((GXe,BK)=>{BK.expor

SyntaxError: Unexpected token {
    at createScript (vm.js:56:10)
    at Object.runInThisContext (vm.js:97:10)
    at Module._compile (module.js:549:28)
    at Object.Module._extensions..js (module.js:586:10)
    at Module.load (module.js:494:32)
    at tryModuleLoad (module.js:453:12)
    at Function.Module._load (module.js:445:3)
    at Module.runMain (module.js:611:10)
    at run (bootstrap_node.js:387:7)
    at startup (bootstrap_node.js:153:9)

[I 2024-06-26 18:31:55.884 ServerApp] Package jupyterlab took 0.0000s to import
[I 2024-06-26 18:31:56.376 ServerApp] Package jupyter_lsp took 0.4918s to import
[W 2024-06-26 18:31:56.376 ServerApp] A `_jupyter_server_extension_points` function was not found in jupyter_lsp. Instead, a `_jupyter_server_extension_paths` function was found and will be used for now. This function name will be deprecated in future releases of Jupyter Server.
[I 2024-06-26 18:31:56.631 ServerApp] Package jupyter_server_terminals took 0.2544s to import
[I 2024-06-26 18:31:56.631 ServerApp] Package notebook took 0.0000s to import
[I 2024-06-26 18:31:56.645 ServerApp] Package notebook_shim took 0.0000s to import
[W 2024-06-26 18:31:56.646 ServerApp] A `_jupyter_server_extension_points` function was not found in notebook_shim. Instead, a `_jupyter_server_extension_paths` function was found and will be used for now. This function name will be deprecated in future releases of Jupyter Server.
[I 2024-06-26 18:31:56.672 ServerApp] jupyter_lsp | extension was successfully linked.
[I 2024-06-26 18:31:56.677 ServerApp] jupyter_server_terminals | extension was successfully linked.
[I 2024-06-26 18:31:56.682 ServerApp] jupyterlab | extension was successfully linked.
[W 2024-06-26 18:31:56.715 JupyterNotebookApp] 'password' has moved from NotebookApp to ServerApp. This config will be passed to ServerApp. Be sure to update your config before our next release.
[W 2024-06-26 18:31:56.717 ServerApp] ServerApp.password config is deprecated in 2.0. Use PasswordIdentityProvider.hashed_password.
[I 2024-06-26 18:31:56.717 ServerApp] notebook | extension was successfully linked.
[I 2024-06-26 18:32:05.649 ServerApp] notebook_shim | extension was successfully linked.
[I 2024-06-26 18:32:05.971 ServerApp] notebook_shim | extension was successfully loaded.
[I 2024-06-26 18:32:05.972 ServerApp] jupyter_lsp | extension was successfully loaded.
[I 2024-06-26 18:32:05.973 ServerApp] jupyter_server_terminals | extension was successfully loaded.
[I 2024-06-26 18:32:06.109 LabApp] JupyterLab extension loaded from /home/naglemi/miniconda3/envs/mwas/lib/python3.11/site-packages/jupyterlab
[I 2024-06-26 18:32:06.109 LabApp] JupyterLab application directory is /home/naglemi/miniconda3/envs/mwas/share/jupyter/lab
[I 2024-06-26 18:32:06.109 LabApp] Extension Manager is 'pypi'.
[I 2024-06-26 18:32:06.111 ServerApp] jupyterlab | extension was successfully loaded.
[I 2024-06-26 18:32:06.118 ServerApp] notebook | extension was successfully loaded.
[I 2024-06-26 18:32:06.119 ServerApp] Serving notebooks from local directory: /expanse/lustre/projects/jhu152/naglemi/mwas/CpGWAS
[I 2024-06-26 18:32:06.119 ServerApp] Jupyter Server 2.10.0 is running at:
[I 2024-06-26 18:32:06.119 ServerApp] http://localhost:8888/lab
[I 2024-06-26 18:32:06.119 ServerApp]     http://127.0.0.1:8888/lab
[I 2024-06-26 18:32:06.119 ServerApp] Use Control-C to stop this server and shut down all kernels (twice to skip confirmation).
[?1049h[22;0;0t[1;24r(B[m[4l[?7h[?1h=[39;49m[39;49m[37m[40m[H[2J[37m[40m[J(B[m[39;49m[37m[40m[39;49m[37m[40m[J[39;49m(B[m[22d[93m[44mGetting file://localhost/home/naglemi/.local/share/jupyter/runtime/jpserver-102[K[39;49m(B[m

[24;1H[?1049l[23;0;0t[?1l>[I 2024-06-26 18:32:11.604 ServerApp] Skipped non-installed server(s): bash-language-server, dockerfile-language-server-nodejs, javascript-typescript-langserver, jedi-language-server, julia-language-server, pyright, python-language-server, python-lsp-server, r-languageserver, sql-language-server, texlab, typescript-language-server, unified-language-server, vscode-css-languageserver-bin, vscode-html-languageserver-bin, vscode-json-languageserver-bin, yaml-language-server
[I 2024-06-26 18:34:23.151 ServerApp] 302 GET / (@127.0.0.1) 0.51ms
[I 2024-06-26 18:34:32.556 ServerApp] 302 GET / (@127.0.0.1) 0.51ms
0.02s - Debugger warning: It seems that frozen modules are being used, which may
0.00s - make the debugger miss breakpoints. Please pass -Xfrozen_modules=off
0.00s - to python to disable frozen modules.
0.00s - Note: Debugging will proceed. Set PYDEVD_DISABLE_FILE_VALIDATION=1 to disable this validation.
[W 2024-06-26 18:34:37.920 ServerApp] 404 GET /apple-touch-icon-precomposed.png (@127.0.0.1) 683.10ms referer=None
[W 2024-06-26 18:34:38.240 ServerApp] 404 GET /apple-touch-icon.png (@127.0.0.1) 0.90ms referer=None
[W 2024-06-26 18:34:39.575 LabApp] Could not determine jupyterlab build status without nodejs
[W 2024-06-26 18:34:40.691 ServerApp] 404 GET /api/contents/mwas/CpGWAS/scripts/Untitled15.ipynb?content=0&1719452080568 (127.0.0.1): No such file or directory: mwas/CpGWAS/scripts/Untitled15.ipynb
[W 2024-06-26 18:34:40.692 ServerApp] wrote error: 'No such file or directory: mwas/CpGWAS/scripts/Untitled15.ipynb'
    Traceback (most recent call last):
      File "/home/naglemi/miniconda3/envs/mwas/lib/python3.11/site-packages/tornado/web.py", line 1786, in _execute
        result = await result
                 ^^^^^^^^^^^^
      File "/home/naglemi/miniconda3/envs/mwas/lib/python3.11/site-packages/jupyter_server/services/contents/handlers.py", line 121, in get
        model = await ensure_async(
                ^^^^^^^^^^^^^^^^^^^
      File "/home/naglemi/miniconda3/envs/mwas/lib/python3.11/site-packages/jupyter_core/utils/__init__.py", line 189, in ensure_async
        result = await obj
                 ^^^^^^^^^
      File "/home/naglemi/miniconda3/envs/mwas/lib/python3.11/site-packages/jupyter_server/services/contents/filemanager.py", line 863, in get
        raise web.HTTPError(404, "No such file or directory: %s" % path)
    tornado.web.HTTPError: HTTP 404: Not Found (No such file or directory: mwas/CpGWAS/scripts/Untitled15.ipynb)
[W 2024-06-26 18:34:40.749 ServerApp] 404 GET /api/contents/mwas/CpGWAS/scripts/Untitled15.ipynb?content=0&1719452080568 (3f38821adc424272adcb326f4f5b79cc@127.0.0.1) 58.19ms referer=http://localhost:8892/lab?
[W 2024-06-26 18:34:40.768 ServerApp] 404 GET /api/contents/mwas/CpGWAS/scripts/18_overlap_risk_loci_mwas_gwas.ipynb?content=0&1719452080568 (127.0.0.1): No such file or directory: mwas/CpGWAS/scripts/18_overlap_risk_loci_mwas_gwas.ipynb
[W 2024-06-26 18:34:40.768 ServerApp] wrote error: 'No such file or directory: mwas/CpGWAS/scripts/18_overlap_risk_loci_mwas_gwas.ipynb'
    Traceback (most recent call last):
      File "/home/naglemi/miniconda3/envs/mwas/lib/python3.11/site-packages/tornado/web.py", line 1786, in _execute
        result = await result
                 ^^^^^^^^^^^^
      File "/home/naglemi/miniconda3/envs/mwas/lib/python3.11/site-packages/jupyter_server/services/contents/handlers.py", line 121, in get
        model = await ensure_async(
                ^^^^^^^^^^^^^^^^^^^
      File "/home/naglemi/miniconda3/envs/mwas/lib/python3.11/site-packages/jupyter_core/utils/__init__.py", line 189, in ensure_async
        result = await obj
                 ^^^^^^^^^
      File "/home/naglemi/miniconda3/envs/mwas/lib/python3.11/site-packages/jupyter_server/services/contents/filemanager.py", line 863, in get
        raise web.HTTPError(404, "No such file or directory: %s" % path)
    tornado.web.HTTPError: HTTP 404: Not Found (No such file or directory: mwas/CpGWAS/scripts/18_overlap_risk_loci_mwas_gwas.ipynb)
[W 2024-06-26 18:34:40.769 ServerApp] 404 GET /api/contents/mwas/CpGWAS/scripts/18_overlap_risk_loci_mwas_gwas.ipynb?content=0&1719452080568 (3f38821adc424272adcb326f4f5b79cc@127.0.0.1) 0.87ms referer=http://localhost:8892/lab?
[W 2024-06-26 18:34:40.769 ServerApp] 404 GET /api/contents/mwas/CpGWAS/scripts/13_GWAS_to_MWAS.ipynb?content=0&1719452080568 (127.0.0.1): No such file or directory: mwas/CpGWAS/scripts/13_GWAS_to_MWAS.ipynb
[W 2024-06-26 18:34:40.769 ServerApp] wrote error: 'No such file or directory: mwas/CpGWAS/scripts/13_GWAS_to_MWAS.ipynb'
    Traceback (most recent call last):
      File "/home/naglemi/miniconda3/envs/mwas/lib/python3.11/site-packages/tornado/web.py", line 1786, in _execute
        result = await result
                 ^^^^^^^^^^^^
      File "/home/naglemi/miniconda3/envs/mwas/lib/python3.11/site-packages/jupyter_server/services/contents/handlers.py", line 121, in get
        model = await ensure_async(
                ^^^^^^^^^^^^^^^^^^^
      File "/home/naglemi/miniconda3/envs/mwas/lib/python3.11/site-packages/jupyter_core/utils/__init__.py", line 189, in ensure_async
        result = await obj
                 ^^^^^^^^^
      File "/home/naglemi/miniconda3/envs/mwas/lib/python3.11/site-packages/jupyter_server/services/contents/filemanager.py", line 863, in get
        raise web.HTTPError(404, "No such file or directory: %s" % path)
    tornado.web.HTTPError: HTTP 404: Not Found (No such file or directory: mwas/CpGWAS/scripts/13_GWAS_to_MWAS.ipynb)
[W 2024-06-26 18:34:40.770 ServerApp] 404 GET /api/contents/mwas/CpGWAS/scripts/13_GWAS_to_MWAS.ipynb?content=0&1719452080568 (3f38821adc424272adcb326f4f5b79cc@127.0.0.1) 0.78ms referer=http://localhost:8892/lab?
[W 2024-06-26 18:34:40.770 ServerApp] 404 GET /api/contents/mwas/CpGWAS/scripts/13.9_format_stage1_outputs_into_table.ipynb?content=0&1719452080569 (127.0.0.1): No such file or directory: mwas/CpGWAS/scripts/13.9_format_stage1_outputs_into_table.ipynb
[W 2024-06-26 18:34:40.770 ServerApp] wrote error: 'No such file or directory: mwas/CpGWAS/scripts/13.9_format_stage1_outputs_into_table.ipynb'
    Traceback (most recent call last):
      File "/home/naglemi/miniconda3/envs/mwas/lib/python3.11/site-packages/tornado/web.py", line 1786, in _execute
        result = await result
                 ^^^^^^^^^^^^
      File "/home/naglemi/miniconda3/envs/mwas/lib/python3.11/site-packages/jupyter_server/services/contents/handlers.py", line 121, in get
        model = await ensure_async(
                ^^^^^^^^^^^^^^^^^^^
      File "/home/naglemi/miniconda3/envs/mwas/lib/python3.11/site-packages/jupyter_core/utils/__init__.py", line 189, in ensure_async
        result = await obj
                 ^^^^^^^^^
      File "/home/naglemi/miniconda3/envs/mwas/lib/python3.11/site-packages/jupyter_server/services/contents/filemanager.py", line 863, in get
        raise web.HTTPError(404, "No such file or directory: %s" % path)
    tornado.web.HTTPError: HTTP 404: Not Found (No such file or directory: mwas/CpGWAS/scripts/13.9_format_stage1_outputs_into_table.ipynb)
[W 2024-06-26 18:34:40.771 ServerApp] 404 GET /api/contents/mwas/CpGWAS/scripts/13.9_format_stage1_outputs_into_table.ipynb?content=0&1719452080569 (3f38821adc424272adcb326f4f5b79cc@127.0.0.1) 0.91ms referer=http://localhost:8892/lab?
[W 2024-06-26 18:34:40.771 ServerApp] 404 GET /api/contents/mwas/CpGWAS/scripts/16_Make_tables_stage2_MWAS_a3-faster.ipynb?content=0&1719452080569 (127.0.0.1): No such file or directory: mwas/CpGWAS/scripts/16_Make_tables_stage2_MWAS_a3-faster.ipynb
[W 2024-06-26 18:34:40.771 ServerApp] wrote error: 'No such file or directory: mwas/CpGWAS/scripts/16_Make_tables_stage2_MWAS_a3-faster.ipynb'
    Traceback (most recent call last):
      File "/home/naglemi/miniconda3/envs/mwas/lib/python3.11/site-packages/tornado/web.py", line 1786, in _execute
        result = await result
                 ^^^^^^^^^^^^
      File "/home/naglemi/miniconda3/envs/mwas/lib/python3.11/site-packages/jupyter_server/services/contents/handlers.py", line 121, in get
        model = await ensure_async(
                ^^^^^^^^^^^^^^^^^^^
      File "/home/naglemi/miniconda3/envs/mwas/lib/python3.11/site-packages/jupyter_core/utils/__init__.py", line 189, in ensure_async
        result = await obj
                 ^^^^^^^^^
      File "/home/naglemi/miniconda3/envs/mwas/lib/python3.11/site-packages/jupyter_server/services/contents/filemanager.py", line 863, in get
        raise web.HTTPError(404, "No such file or directory: %s" % path)
    tornado.web.HTTPError: HTTP 404: Not Found (No such file or directory: mwas/CpGWAS/scripts/16_Make_tables_stage2_MWAS_a3-faster.ipynb)
[W 2024-06-26 18:34:40.772 ServerApp] 404 GET /api/contents/mwas/CpGWAS/scripts/16_Make_tables_stage2_MWAS_a3-faster.ipynb?content=0&1719452080569 (3f38821adc424272adcb326f4f5b79cc@127.0.0.1) 1.48ms referer=http://localhost:8892/lab?
[I 2024-06-26 18:34:41.115 ServerApp] New terminal with automatic name: 7
[W 2024-06-26 18:34:42.372 ServerApp] 404 GET /api/contents/mwas/CpGWAS/scripts?1719452082252 (127.0.0.1): No such file or directory: mwas/CpGWAS/scripts
[W 2024-06-26 18:34:42.372 ServerApp] wrote error: 'No such file or directory: mwas/CpGWAS/scripts'
    Traceback (most recent call last):
      File "/home/naglemi/miniconda3/envs/mwas/lib/python3.11/site-packages/tornado/web.py", line 1786, in _execute
        result = await result
                 ^^^^^^^^^^^^
      File "/home/naglemi/miniconda3/envs/mwas/lib/python3.11/site-packages/jupyter_server/services/contents/handlers.py", line 121, in get
        model = await ensure_async(
                ^^^^^^^^^^^^^^^^^^^
      File "/home/naglemi/miniconda3/envs/mwas/lib/python3.11/site-packages/jupyter_core/utils/__init__.py", line 189, in ensure_async
        result = await obj
                 ^^^^^^^^^
      File "/home/naglemi/miniconda3/envs/mwas/lib/python3.11/site-packages/jupyter_server/services/contents/filemanager.py", line 863, in get
        raise web.HTTPError(404, "No such file or directory: %s" % path)
    tornado.web.HTTPError: HTTP 404: Not Found (No such file or directory: mwas/CpGWAS/scripts)
[W 2024-06-26 18:34:42.372 ServerApp] 404 GET /api/contents/mwas/CpGWAS/scripts?1719452082252 (3f38821adc424272adcb326f4f5b79cc@127.0.0.1) 1.12ms referer=http://localhost:8892/lab?
[I 2024-06-26 18:38:38.579 ServerApp] Kernel started: 15827b2e-44b3-4ebd-b5fa-924596a0443e
[I 2024-06-26 18:38:41.368 ServerApp] Connecting to kernel 15827b2e-44b3-4ebd-b5fa-924596a0443e.
[I 2024-06-26 18:38:41.370 ServerApp] Connecting to kernel 15827b2e-44b3-4ebd-b5fa-924596a0443e.
[I 2024-06-26 18:38:41.370 ServerApp] Connecting to kernel 15827b2e-44b3-4ebd-b5fa-924596a0443e.
[I 2024-06-26 18:39:56.153 ServerApp] Kernel restarted: 15827b2e-44b3-4ebd-b5fa-924596a0443e
[I 2024-06-26 18:39:56.262 ServerApp] Starting buffering for 15827b2e-44b3-4ebd-b5fa-924596a0443e:742ddba3-3488-40d8-b3ae-aa58679eb91d
[I 2024-06-26 18:39:56.349 ServerApp] Connecting to kernel 15827b2e-44b3-4ebd-b5fa-924596a0443e.
[I 2024-06-26 18:39:56.349 ServerApp] Restoring connection for 15827b2e-44b3-4ebd-b5fa-924596a0443e:742ddba3-3488-40d8-b3ae-aa58679eb91d
[I 2024-06-26 18:40:38.226 ServerApp] Saving file at /scripts/18_overlap_risk_loci_mwas_gwas.ipynb
[I 2024-06-26 18:40:39.409 ServerApp] New terminal with automatic name: 1
[I 2024-06-26 18:40:53.902 ServerApp] New terminal with automatic name: 2
[I 2024-06-26 18:42:23.143 ServerApp] AsyncIOLoopKernelRestarter: restarting kernel (1/5), keep random ports
[W 2024-06-26 18:42:23.144 ServerApp] kernel 15827b2e-44b3-4ebd-b5fa-924596a0443e restarted
[I 2024-06-26 18:42:23.398 ServerApp] Starting buffering for 15827b2e-44b3-4ebd-b5fa-924596a0443e:742ddba3-3488-40d8-b3ae-aa58679eb91d
[I 2024-06-26 18:42:23.552 ServerApp] Connecting to kernel 15827b2e-44b3-4ebd-b5fa-924596a0443e.
[I 2024-06-26 18:42:23.552 ServerApp] Restoring connection for 15827b2e-44b3-4ebd-b5fa-924596a0443e:742ddba3-3488-40d8-b3ae-aa58679eb91d
[I 2024-06-26 18:42:38.763 ServerApp] Saving file at /scripts/18_overlap_risk_loci_mwas_gwas.ipynb
[I 2024-06-26 18:43:01.756 ServerApp] Kernel restarted: 15827b2e-44b3-4ebd-b5fa-924596a0443e
[I 2024-06-26 18:43:01.839 ServerApp] Starting buffering for 15827b2e-44b3-4ebd-b5fa-924596a0443e:742ddba3-3488-40d8-b3ae-aa58679eb91d
[I 2024-06-26 18:43:02.002 ServerApp] Connecting to kernel 15827b2e-44b3-4ebd-b5fa-924596a0443e.
[I 2024-06-26 18:43:02.002 ServerApp] Restoring connection for 15827b2e-44b3-4ebd-b5fa-924596a0443e:742ddba3-3488-40d8-b3ae-aa58679eb91d
[I 2024-06-26 18:44:39.397 ServerApp] Saving file at /scripts/18_overlap_risk_loci_mwas_gwas.ipynb
[I 2024-06-26 18:45:19.747 ServerApp] AsyncIOLoopKernelRestarter: restarting kernel (1/5), keep random ports
[W 2024-06-26 18:45:19.748 ServerApp] kernel 15827b2e-44b3-4ebd-b5fa-924596a0443e restarted
[I 2024-06-26 18:45:19.832 ServerApp] Starting buffering for 15827b2e-44b3-4ebd-b5fa-924596a0443e:742ddba3-3488-40d8-b3ae-aa58679eb91d
[I 2024-06-26 18:45:19.989 ServerApp] Connecting to kernel 15827b2e-44b3-4ebd-b5fa-924596a0443e.
[I 2024-06-26 18:45:19.989 ServerApp] Restoring connection for 15827b2e-44b3-4ebd-b5fa-924596a0443e:742ddba3-3488-40d8-b3ae-aa58679eb91d
[I 2024-06-26 18:46:40.081 ServerApp] Saving file at /scripts/18_overlap_risk_loci_mwas_gwas.ipynb
[I 2024-06-26 18:49:01.183 ServerApp] Kernel shutdown: 15827b2e-44b3-4ebd-b5fa-924596a0443e
[I 2024-06-26 18:49:01.509 ServerApp] EOF on FD 31; stopping reading
[I 2024-06-26 18:49:01.610 ServerApp] Terminal 2 closed
[I 2024-06-26 18:49:01.610 ServerApp] EOF on FD 25; stopping reading
[I 2024-06-26 18:49:01.710 ServerApp] Terminal 1 closed
[I 2024-06-26 18:49:01.711 ServerApp] EOF on FD 17; stopping reading
[I 2024-06-26 18:49:01.812 ServerApp] Terminal 7 closed
Future exception was never retrieved
future: <Future finished exception=AssertionError()>
Traceback (most recent call last):
  File "/home/naglemi/miniconda3/envs/mwas/lib/python3.11/site-packages/tornado/gen.py", line 234, in wrapper
    yielded = ctx_run(next, result)
              ^^^^^^^^^^^^^^^^^^^^^
  File "/home/naglemi/miniconda3/envs/mwas/lib/python3.11/site-packages/terminado/websocket.py", line 93, in on_message
    assert self.terminal is not None
AssertionError
[I 2024-06-26 18:49:02.063 ServerApp] Shutting down on /api/shutdown request.
[I 2024-06-26 18:49:02.093 ServerApp] Shutting down 5 extensions
slurmstepd: error: Detected 2 oom_kill events in StepId=31693453.batch. Some of the step tasks have been OOM Killed.
