Fail to get yarn configuration. /home/naglemi/miniconda3/envs/mwas/lib/python3.11/site-packages/jupyterlab/staging/yarn.js:4
(()=>{var Qge=Object.create;var AS=Object.defineProperty;var bge=Object.getOwnPropertyDescriptor;var Sge=Object.getOwnPropertyNames;var vge=Object.getPrototypeOf,xge=Object.prototype.hasOwnProperty;var J=(r=>typeof require<"u"?require:typeof Proxy<"u"?new Proxy(r,{get:(e,t)=>(typeof require<"u"?require:e)[t]}):r)(function(r){if(typeof require<"u")return require.apply(this,arguments);throw new Error('Dynamic require of "'+r+'" is not supported')});var Pge=(r,e)=>()=>(r&&(e=r(r=0)),e);var w=(r,e)=>()=>(e||r((e={exports:{}}).exports,e),e.exports),ut=(r,e)=>{for(var t in e)AS(r,t,{get:e[t],enumerable:!0})},Dge=(r,e,t,i)=>{if(e&&typeof e=="object"||typeof e=="function")for(let n of Sge(e))!xge.call(r,n)&&n!==t&&AS(r,n,{get:()=>e[n],enumerable:!(i=bge(e,n))||i.enumerable});return r};var Pe=(r,e,t)=>(t=r!=null?Qge(vge(r)):{},Dge(e||!r||!r.__esModule?AS(t,"default",{value:r,enumerable:!0}):t,r));var QK=w((GXe,BK)=>{BK.expor

SyntaxError: Unexpected token {
    at createScript (vm.js:56:10)
    at Object.runInThisContext (vm.js:97:10)
    at Module._compile (module.js:549:28)
    at Object.Module._extensions..js (module.js:586:10)
    at Module.load (module.js:494:32)
    at tryModuleLoad (module.js:453:12)
    at Function.Module._load (module.js:445:3)
    at Module.runMain (module.js:611:10)
    at run (bootstrap_node.js:387:7)
    at startup (bootstrap_node.js:153:9)

[I 2024-06-26 18:52:40.810 ServerApp] Package jupyterlab took 0.0000s to import
[I 2024-06-26 18:52:40.829 ServerApp] Package jupyter_lsp took 0.0182s to import
[W 2024-06-26 18:52:40.829 ServerApp] A `_jupyter_server_extension_points` function was not found in jupyter_lsp. Instead, a `_jupyter_server_extension_paths` function was found and will be used for now. This function name will be deprecated in future releases of Jupyter Server.
[I 2024-06-26 18:52:40.837 ServerApp] Package jupyter_server_terminals took 0.0078s to import
[I 2024-06-26 18:52:40.837 ServerApp] Package notebook took 0.0000s to import
[I 2024-06-26 18:52:40.839 ServerApp] Package notebook_shim took 0.0000s to import
[W 2024-06-26 18:52:40.839 ServerApp] A `_jupyter_server_extension_points` function was not found in notebook_shim. Instead, a `_jupyter_server_extension_paths` function was found and will be used for now. This function name will be deprecated in future releases of Jupyter Server.
[I 2024-06-26 18:52:40.839 ServerApp] jupyter_lsp | extension was successfully linked.
[I 2024-06-26 18:52:40.843 ServerApp] jupyter_server_terminals | extension was successfully linked.
[I 2024-06-26 18:52:40.848 ServerApp] jupyterlab | extension was successfully linked.
[W 2024-06-26 18:52:40.851 JupyterNotebookApp] 'password' has moved from NotebookApp to ServerApp. This config will be passed to ServerApp. Be sure to update your config before our next release.
[W 2024-06-26 18:52:40.853 ServerApp] ServerApp.password config is deprecated in 2.0. Use PasswordIdentityProvider.hashed_password.
[I 2024-06-26 18:52:40.853 ServerApp] notebook | extension was successfully linked.
[I 2024-06-26 18:52:41.154 ServerApp] notebook_shim | extension was successfully linked.
[I 2024-06-26 18:52:41.177 ServerApp] notebook_shim | extension was successfully loaded.
[I 2024-06-26 18:52:41.179 ServerApp] jupyter_lsp | extension was successfully loaded.
[I 2024-06-26 18:52:41.179 ServerApp] jupyter_server_terminals | extension was successfully loaded.
[I 2024-06-26 18:52:41.189 LabApp] JupyterLab extension loaded from /home/naglemi/miniconda3/envs/mwas/lib/python3.11/site-packages/jupyterlab
[I 2024-06-26 18:52:41.190 LabApp] JupyterLab application directory is /home/naglemi/miniconda3/envs/mwas/share/jupyter/lab
[I 2024-06-26 18:52:41.190 LabApp] Extension Manager is 'pypi'.
[I 2024-06-26 18:52:41.191 ServerApp] jupyterlab | extension was successfully loaded.
[I 2024-06-26 18:52:41.195 ServerApp] notebook | extension was successfully loaded.
[I 2024-06-26 18:52:41.195 ServerApp] Serving notebooks from local directory: /expanse/lustre/projects/jhu152/naglemi/mwas/CpGWAS
[I 2024-06-26 18:52:41.195 ServerApp] Jupyter Server 2.10.0 is running at:
[I 2024-06-26 18:52:41.195 ServerApp] http://localhost:8888/lab
[I 2024-06-26 18:52:41.195 ServerApp]     http://127.0.0.1:8888/lab
[I 2024-06-26 18:52:41.195 ServerApp] Use Control-C to stop this server and shut down all kernels (twice to skip confirmation).
[?1049h[22;0;0t[1;24r(B[m[4l[?7h[?1h=[39;49m[39;49m[37m[40m[H[2J[37m[40m[J(B[m[39;49m[37m[40m[39;49m[37m[40m[J[39;49m(B[m[22d[93m[44mGetting file://localhost/home/naglemi/.local/share/jupyter/runtime/jpserver-138[K[39;49m(B[m

[24;1H[?1049l[23;0;0t[?1l>[I 2024-06-26 18:52:42.057 ServerApp] Skipped non-installed server(s): bash-language-server, dockerfile-language-server-nodejs, javascript-typescript-langserver, jedi-language-server, julia-language-server, pyright, python-language-server, python-lsp-server, r-languageserver, sql-language-server, texlab, typescript-language-server, unified-language-server, vscode-css-languageserver-bin, vscode-html-languageserver-bin, vscode-json-languageserver-bin, yaml-language-server
0.00s - Debugger warning: It seems that frozen modules are being used, which may
0.00s - make the debugger miss breakpoints. Please pass -Xfrozen_modules=off
0.00s - to python to disable frozen modules.
0.00s - Note: Debugging will proceed. Set PYDEVD_DISABLE_FILE_VALIDATION=1 to disable this validation.
[W 2024-06-26 18:53:09.070 LabApp] Could not determine jupyterlab build status without nodejs
[I 2024-06-26 18:53:09.724 ServerApp] New terminal with automatic name: 7
[I 2024-06-26 18:53:09.845 ServerApp] New terminal with automatic name: 1
[I 2024-06-26 18:53:09.974 ServerApp] New terminal with automatic name: 2
[I 2024-06-26 18:53:17.935 ServerApp] Kernel started: bc9bf65f-d14e-4cfe-a1d4-5d0ddc95933c
[I 2024-06-26 18:53:18.802 ServerApp] Connecting to kernel bc9bf65f-d14e-4cfe-a1d4-5d0ddc95933c.
[I 2024-06-26 18:53:18.802 ServerApp] Connecting to kernel bc9bf65f-d14e-4cfe-a1d4-5d0ddc95933c.
[I 2024-06-26 18:53:18.841 ServerApp] Connecting to kernel bc9bf65f-d14e-4cfe-a1d4-5d0ddc95933c.
[I 2024-06-26 18:53:28.888 ServerApp] Kernel restarted: bc9bf65f-d14e-4cfe-a1d4-5d0ddc95933c
[I 2024-06-26 18:53:28.976 ServerApp] Starting buffering for bc9bf65f-d14e-4cfe-a1d4-5d0ddc95933c:40bdb373-4ba6-4471-ada9-95e04e5d0ec3
[I 2024-06-26 18:53:29.068 ServerApp] Connecting to kernel bc9bf65f-d14e-4cfe-a1d4-5d0ddc95933c.
[I 2024-06-26 18:53:29.068 ServerApp] Restoring connection for bc9bf65f-d14e-4cfe-a1d4-5d0ddc95933c:40bdb373-4ba6-4471-ada9-95e04e5d0ec3
[I 2024-06-26 18:55:17.737 ServerApp] Saving file at /scripts/18_overlap_risk_loci_mwas_gwas.ipynb
[I 2024-06-26 18:57:18.373 ServerApp] Saving file at /scripts/18_overlap_risk_loci_mwas_gwas.ipynb
[I 2024-06-26 19:03:19.560 ServerApp] Saving file at /scripts/18_overlap_risk_loci_mwas_gwas.ipynb
[I 2024-06-26 19:05:20.408 ServerApp] Saving file at /scripts/18_overlap_risk_loci_mwas_gwas.ipynb
[I 2024-06-26 19:07:21.203 ServerApp] Saving file at /scripts/18_overlap_risk_loci_mwas_gwas.ipynb
[I 2024-06-26 19:08:41.222 ServerApp] Kernel started: b42a0e13-4e2b-418f-bd0b-7a7960e6ba08
[I 2024-06-26 19:08:41.223 ServerApp] Kernel shutdown: bc9bf65f-d14e-4cfe-a1d4-5d0ddc95933c
0.00s - Debugger warning: It seems that frozen modules are being used, which may
0.00s - make the debugger miss breakpoints. Please pass -Xfrozen_modules=off
0.00s - to python to disable frozen modules.
0.00s - Note: Debugging will proceed. Set PYDEVD_DISABLE_FILE_VALIDATION=1 to disable this validation.
[I 2024-06-26 19:08:42.153 ServerApp] Connecting to kernel b42a0e13-4e2b-418f-bd0b-7a7960e6ba08.
[I 2024-06-26 19:08:42.154 ServerApp] Connecting to kernel b42a0e13-4e2b-418f-bd0b-7a7960e6ba08.
[I 2024-06-26 19:09:21.948 ServerApp] Saving file at /scripts/18_overlap_risk_loci_mwas_gwas.ipynb
[I 2024-06-26 19:13:22.547 ServerApp] Saving file at /scripts/18_overlap_risk_loci_mwas_gwas.ipynb
[I 2024-06-26 19:53:23.378 ServerApp] Saving file at /scripts/18_overlap_risk_loci_mwas_gwas.ipynb
[I 2024-06-26 19:54:28.758 ServerApp] Kernel restarted: b42a0e13-4e2b-418f-bd0b-7a7960e6ba08
[I 2024-06-26 19:54:28.933 ServerApp] Starting buffering for b42a0e13-4e2b-418f-bd0b-7a7960e6ba08:40bdb373-4ba6-4471-ada9-95e04e5d0ec3
[I 2024-06-26 19:54:29.096 ServerApp] Connecting to kernel b42a0e13-4e2b-418f-bd0b-7a7960e6ba08.
[I 2024-06-26 19:54:29.096 ServerApp] Restoring connection for b42a0e13-4e2b-418f-bd0b-7a7960e6ba08:40bdb373-4ba6-4471-ada9-95e04e5d0ec3
0.00s - Debugger warning: It seems that frozen modules are being used, which may
0.00s - make the debugger miss breakpoints. Please pass -Xfrozen_modules=off
0.00s - to python to disable frozen modules.
0.00s - Note: Debugging will proceed. Set PYDEVD_DISABLE_FILE_VALIDATION=1 to disable this validation.
[I 2024-06-26 19:55:24.544 ServerApp] Saving file at /scripts/18_overlap_risk_loci_mwas_gwas.ipynb
[I 2024-06-26 19:57:27.800 ServerApp] Saving file at /scripts/18_overlap_risk_loci_mwas_gwas.ipynb
[I 2024-06-26 20:09:22.343 ServerApp] Kernel restarted: b42a0e13-4e2b-418f-bd0b-7a7960e6ba08
[I 2024-06-26 20:09:22.493 ServerApp] Starting buffering for b42a0e13-4e2b-418f-bd0b-7a7960e6ba08:40bdb373-4ba6-4471-ada9-95e04e5d0ec3
[I 2024-06-26 20:09:22.646 ServerApp] Connecting to kernel b42a0e13-4e2b-418f-bd0b-7a7960e6ba08.
[I 2024-06-26 20:09:22.646 ServerApp] Restoring connection for b42a0e13-4e2b-418f-bd0b-7a7960e6ba08:40bdb373-4ba6-4471-ada9-95e04e5d0ec3
0.00s - Debugger warning: It seems that frozen modules are being used, which may
0.00s - make the debugger miss breakpoints. Please pass -Xfrozen_modules=off
0.00s - to python to disable frozen modules.
0.00s - Note: Debugging will proceed. Set PYDEVD_DISABLE_FILE_VALIDATION=1 to disable this validation.
[I 2024-06-26 20:09:28.685 ServerApp] Saving file at /scripts/18_overlap_risk_loci_mwas_gwas.ipynb
[I 2024-06-26 20:13:24.940 ServerApp] Kernel restarted: b42a0e13-4e2b-418f-bd0b-7a7960e6ba08
[I 2024-06-26 20:13:25.040 ServerApp] Starting buffering for b42a0e13-4e2b-418f-bd0b-7a7960e6ba08:40bdb373-4ba6-4471-ada9-95e04e5d0ec3
[I 2024-06-26 20:13:25.130 ServerApp] Connecting to kernel b42a0e13-4e2b-418f-bd0b-7a7960e6ba08.
[I 2024-06-26 20:13:25.130 ServerApp] Restoring connection for b42a0e13-4e2b-418f-bd0b-7a7960e6ba08:40bdb373-4ba6-4471-ada9-95e04e5d0ec3
0.00s - Debugger warning: It seems that frozen modules are being used, which may
0.00s - make the debugger miss breakpoints. Please pass -Xfrozen_modules=off
0.00s - to python to disable frozen modules.
0.00s - Note: Debugging will proceed. Set PYDEVD_DISABLE_FILE_VALIDATION=1 to disable this validation.
[I 2024-06-26 20:13:29.612 ServerApp] Saving file at /scripts/18_overlap_risk_loci_mwas_gwas.ipynb
[I 2024-06-26 20:17:30.226 ServerApp] Saving file at /scripts/18_overlap_risk_loci_mwas_gwas.ipynb
[I 2024-06-26 20:17:40.298 ServerApp] Kernel restarted: b42a0e13-4e2b-418f-bd0b-7a7960e6ba08
[I 2024-06-26 20:17:40.377 ServerApp] Starting buffering for b42a0e13-4e2b-418f-bd0b-7a7960e6ba08:40bdb373-4ba6-4471-ada9-95e04e5d0ec3
[I 2024-06-26 20:17:40.535 ServerApp] Connecting to kernel b42a0e13-4e2b-418f-bd0b-7a7960e6ba08.
[I 2024-06-26 20:17:40.535 ServerApp] Restoring connection for b42a0e13-4e2b-418f-bd0b-7a7960e6ba08:40bdb373-4ba6-4471-ada9-95e04e5d0ec3
0.00s - Debugger warning: It seems that frozen modules are being used, which may
0.00s - make the debugger miss breakpoints. Please pass -Xfrozen_modules=off
0.00s - to python to disable frozen modules.
0.00s - Note: Debugging will proceed. Set PYDEVD_DISABLE_FILE_VALIDATION=1 to disable this validation.
[I 2024-06-26 20:17:42.903 ServerApp] Kernel restarted: b42a0e13-4e2b-418f-bd0b-7a7960e6ba08
[I 2024-06-26 20:17:43.052 ServerApp] Starting buffering for b42a0e13-4e2b-418f-bd0b-7a7960e6ba08:40bdb373-4ba6-4471-ada9-95e04e5d0ec3
[I 2024-06-26 20:17:43.218 ServerApp] Connecting to kernel b42a0e13-4e2b-418f-bd0b-7a7960e6ba08.
[I 2024-06-26 20:17:43.218 ServerApp] Restoring connection for b42a0e13-4e2b-418f-bd0b-7a7960e6ba08:40bdb373-4ba6-4471-ada9-95e04e5d0ec3
0.00s - Debugger warning: It seems that frozen modules are being used, which may
0.00s - make the debugger miss breakpoints. Please pass -Xfrozen_modules=off
0.00s - to python to disable frozen modules.
0.00s - Note: Debugging will proceed. Set PYDEVD_DISABLE_FILE_VALIDATION=1 to disable this validation.
[I 2024-06-26 20:19:30.960 ServerApp] Saving file at /scripts/18_overlap_risk_loci_mwas_gwas.ipynb
[I 2024-06-26 20:27:04.402 ServerApp] Kernel restarted: b42a0e13-4e2b-418f-bd0b-7a7960e6ba08
[I 2024-06-26 20:27:04.702 ServerApp] Starting buffering for b42a0e13-4e2b-418f-bd0b-7a7960e6ba08:40bdb373-4ba6-4471-ada9-95e04e5d0ec3
[I 2024-06-26 20:27:04.858 ServerApp] Connecting to kernel b42a0e13-4e2b-418f-bd0b-7a7960e6ba08.
[I 2024-06-26 20:27:04.858 ServerApp] Restoring connection for b42a0e13-4e2b-418f-bd0b-7a7960e6ba08:40bdb373-4ba6-4471-ada9-95e04e5d0ec3
0.00s - Debugger warning: It seems that frozen modules are being used, which may
0.00s - make the debugger miss breakpoints. Please pass -Xfrozen_modules=off
0.00s - to python to disable frozen modules.
0.00s - Note: Debugging will proceed. Set PYDEVD_DISABLE_FILE_VALIDATION=1 to disable this validation.
[I 2024-06-26 20:27:05.642 ServerApp] Kernel restarted: b42a0e13-4e2b-418f-bd0b-7a7960e6ba08
[I 2024-06-26 20:27:05.826 ServerApp] Starting buffering for b42a0e13-4e2b-418f-bd0b-7a7960e6ba08:40bdb373-4ba6-4471-ada9-95e04e5d0ec3
[I 2024-06-26 20:27:05.985 ServerApp] Connecting to kernel b42a0e13-4e2b-418f-bd0b-7a7960e6ba08.
[I 2024-06-26 20:27:05.985 ServerApp] Restoring connection for b42a0e13-4e2b-418f-bd0b-7a7960e6ba08:40bdb373-4ba6-4471-ada9-95e04e5d0ec3
0.00s - Debugger warning: It seems that frozen modules are being used, which may
0.00s - make the debugger miss breakpoints. Please pass -Xfrozen_modules=off
0.00s - to python to disable frozen modules.
0.00s - Note: Debugging will proceed. Set PYDEVD_DISABLE_FILE_VALIDATION=1 to disable this validation.
[I 2024-06-26 20:27:32.294 ServerApp] Saving file at /scripts/18_overlap_risk_loci_mwas_gwas.ipynb
[I 2024-06-26 20:31:13.544 ServerApp] Kernel restarted: b42a0e13-4e2b-418f-bd0b-7a7960e6ba08
[I 2024-06-26 20:31:13.799 ServerApp] Starting buffering for b42a0e13-4e2b-418f-bd0b-7a7960e6ba08:40bdb373-4ba6-4471-ada9-95e04e5d0ec3
[I 2024-06-26 20:31:13.963 ServerApp] Connecting to kernel b42a0e13-4e2b-418f-bd0b-7a7960e6ba08.
[I 2024-06-26 20:31:13.963 ServerApp] Restoring connection for b42a0e13-4e2b-418f-bd0b-7a7960e6ba08:40bdb373-4ba6-4471-ada9-95e04e5d0ec3
0.00s - Debugger warning: It seems that frozen modules are being used, which may
0.00s - make the debugger miss breakpoints. Please pass -Xfrozen_modules=off
0.00s - to python to disable frozen modules.
0.00s - Note: Debugging will proceed. Set PYDEVD_DISABLE_FILE_VALIDATION=1 to disable this validation.
[I 2024-06-26 20:31:20.809 ServerApp] Saving file at /scripts/18_overlap_risk_loci_mwas_gwas.ipynb
[I 2024-06-26 20:33:21.915 ServerApp] Saving file at /scripts/18_overlap_risk_loci_mwas_gwas.ipynb
[I 2024-06-26 20:38:07.493 ServerApp] Kernel restarted: b42a0e13-4e2b-418f-bd0b-7a7960e6ba08
0.00s - Debugger warning: It seems that frozen modules are being used, which may
0.00s - make the debugger miss breakpoints. Please pass -Xfrozen_modules=off
0.00s - to python to disable frozen modules.
0.00s - Note: Debugging will proceed. Set PYDEVD_DISABLE_FILE_VALIDATION=1 to disable this validation.
[I 2024-06-26 20:38:07.959 ServerApp] Starting buffering for b42a0e13-4e2b-418f-bd0b-7a7960e6ba08:40bdb373-4ba6-4471-ada9-95e04e5d0ec3
[I 2024-06-26 20:38:08.095 ServerApp] Connecting to kernel b42a0e13-4e2b-418f-bd0b-7a7960e6ba08.
[I 2024-06-26 20:38:08.095 ServerApp] Restoring connection for b42a0e13-4e2b-418f-bd0b-7a7960e6ba08:40bdb373-4ba6-4471-ada9-95e04e5d0ec3
[I 2024-06-26 20:39:23.093 ServerApp] Saving file at /scripts/18_overlap_risk_loci_mwas_gwas.ipynb
[I 2024-06-26 20:41:04.552 ServerApp] Kernel restarted: b42a0e13-4e2b-418f-bd0b-7a7960e6ba08
[I 2024-06-26 20:41:04.639 ServerApp] Starting buffering for b42a0e13-4e2b-418f-bd0b-7a7960e6ba08:40bdb373-4ba6-4471-ada9-95e04e5d0ec3
[I 2024-06-26 20:41:04.790 ServerApp] Connecting to kernel b42a0e13-4e2b-418f-bd0b-7a7960e6ba08.
[I 2024-06-26 20:41:04.790 ServerApp] Restoring connection for b42a0e13-4e2b-418f-bd0b-7a7960e6ba08:40bdb373-4ba6-4471-ada9-95e04e5d0ec3
0.00s - Debugger warning: It seems that frozen modules are being used, which may
0.00s - make the debugger miss breakpoints. Please pass -Xfrozen_modules=off
0.00s - to python to disable frozen modules.
0.00s - Note: Debugging will proceed. Set PYDEVD_DISABLE_FILE_VALIDATION=1 to disable this validation.
[I 2024-06-26 20:42:36.652 ServerApp] Saving file at /scripts/18_overlap_risk_loci_mwas_gwas.ipynb
[I 2024-06-26 20:54:30.320 ServerApp] Kernel restarted: b42a0e13-4e2b-418f-bd0b-7a7960e6ba08
[I 2024-06-26 20:54:30.417 ServerApp] Starting buffering for b42a0e13-4e2b-418f-bd0b-7a7960e6ba08:40bdb373-4ba6-4471-ada9-95e04e5d0ec3
[I 2024-06-26 20:54:30.581 ServerApp] Connecting to kernel b42a0e13-4e2b-418f-bd0b-7a7960e6ba08.
[I 2024-06-26 20:54:30.581 ServerApp] Restoring connection for b42a0e13-4e2b-418f-bd0b-7a7960e6ba08:40bdb373-4ba6-4471-ada9-95e04e5d0ec3
0.00s - Debugger warning: It seems that frozen modules are being used, which may
0.00s - make the debugger miss breakpoints. Please pass -Xfrozen_modules=off
0.00s - to python to disable frozen modules.
0.00s - Note: Debugging will proceed. Set PYDEVD_DISABLE_FILE_VALIDATION=1 to disable this validation.
[I 2024-06-26 20:54:36.788 ServerApp] Kernel restarted: b42a0e13-4e2b-418f-bd0b-7a7960e6ba08
[I 2024-06-26 20:54:36.944 ServerApp] Starting buffering for b42a0e13-4e2b-418f-bd0b-7a7960e6ba08:40bdb373-4ba6-4471-ada9-95e04e5d0ec3
[I 2024-06-26 20:54:37.107 ServerApp] Connecting to kernel b42a0e13-4e2b-418f-bd0b-7a7960e6ba08.
[I 2024-06-26 20:54:37.107 ServerApp] Restoring connection for b42a0e13-4e2b-418f-bd0b-7a7960e6ba08:40bdb373-4ba6-4471-ada9-95e04e5d0ec3
0.00s - Debugger warning: It seems that frozen modules are being used, which may
0.00s - make the debugger miss breakpoints. Please pass -Xfrozen_modules=off
0.00s - to python to disable frozen modules.
0.00s - Note: Debugging will proceed. Set PYDEVD_DISABLE_FILE_VALIDATION=1 to disable this validation.
[I 2024-06-26 20:54:37.272 ServerApp] Saving file at /scripts/18_overlap_risk_loci_mwas_gwas.ipynb
[I 2024-06-26 20:56:38.253 ServerApp] Saving file at /scripts/18_overlap_risk_loci_mwas_gwas.ipynb
[I 2024-06-26 21:32:38.745 ServerApp] Saving file at /scripts/18_overlap_risk_loci_mwas_gwas.ipynb
[I 2024-06-26 21:34:39.613 ServerApp] Saving file at /scripts/18_overlap_risk_loci_mwas_gwas.ipynb
[W 2024-06-27 06:29:37.108 ServerApp] WebSocket ping timeout after 119922 ms.
[I 2024-06-27 06:29:42.201 ServerApp] Starting buffering for b42a0e13-4e2b-418f-bd0b-7a7960e6ba08:40bdb373-4ba6-4471-ada9-95e04e5d0ec3
[W 2024-06-27 06:29:46.748 TerminalsExtensionApp] WebSocket ping timeout after 119916 ms.
[W 2024-06-27 06:29:46.748 TerminalsExtensionApp] WebSocket ping timeout after 119849 ms.
[W 2024-06-27 06:29:46.749 TerminalsExtensionApp] WebSocket ping timeout after 119849 ms.
Exception in callback BaseAsyncIOLoop._handle_events(17, 1)
handle: <Handle BaseAsyncIOLoop._handle_events(17, 1)>
Traceback (most recent call last):
  File "/home/naglemi/miniconda3/envs/mwas/lib/python3.11/asyncio/events.py", line 80, in _run
    self._context.run(self._callback, *self._args)
  File "/home/naglemi/miniconda3/envs/mwas/lib/python3.11/site-packages/tornado/platform/asyncio.py", line 192, in _handle_events
    handler_func(fileobj, events)
  File "/home/naglemi/miniconda3/envs/mwas/lib/python3.11/site-packages/terminado/management.py", line 252, in pty_read
    client.on_pty_read(s)
  File "/home/naglemi/miniconda3/envs/mwas/lib/python3.11/site-packages/terminado/websocket.py", line 73, in on_pty_read
    self.send_json_message(["stdout", text])
  File "/home/naglemi/miniconda3/envs/mwas/lib/python3.11/site-packages/terminado/websocket.py", line 77, in send_json_message
    self.write_message(json_msg)
  File "/home/naglemi/miniconda3/envs/mwas/lib/python3.11/site-packages/jupyter_server_terminals/handlers.py", line 57, in write_message
    super().write_message(message, binary=binary)
  File "/home/naglemi/miniconda3/envs/mwas/lib/python3.11/site-packages/tornado/websocket.py", line 331, in write_message
    raise WebSocketClosedError()
tornado.websocket.WebSocketClosedError
Exception in callback BaseAsyncIOLoop._handle_events(17, 1)
handle: <Handle BaseAsyncIOLoop._handle_events(17, 1)>
Traceback (most recent call last):
  File "/home/naglemi/miniconda3/envs/mwas/lib/python3.11/asyncio/events.py", line 80, in _run
    self._context.run(self._callback, *self._args)
  File "/home/naglemi/miniconda3/envs/mwas/lib/python3.11/site-packages/tornado/platform/asyncio.py", line 192, in _handle_events
    handler_func(fileobj, events)
  File "/home/naglemi/miniconda3/envs/mwas/lib/python3.11/site-packages/terminado/management.py", line 252, in pty_read
    client.on_pty_read(s)
  File "/home/naglemi/miniconda3/envs/mwas/lib/python3.11/site-packages/terminado/websocket.py", line 73, in on_pty_read
    self.send_json_message(["stdout", text])
  File "/home/naglemi/miniconda3/envs/mwas/lib/python3.11/site-packages/terminado/websocket.py", line 77, in send_json_message
    self.write_message(json_msg)
  File "/home/naglemi/miniconda3/envs/mwas/lib/python3.11/site-packages/jupyter_server_terminals/handlers.py", line 57, in write_message
    super().write_message(message, binary=binary)
  File "/home/naglemi/miniconda3/envs/mwas/lib/python3.11/site-packages/tornado/websocket.py", line 331, in write_message
    raise WebSocketClosedError()
tornado.websocket.WebSocketClosedError
Exception in callback BaseAsyncIOLoop._handle_events(17, 1)
handle: <Handle BaseAsyncIOLoop._handle_events(17, 1)>
Traceback (most recent call last):
  File "/home/naglemi/miniconda3/envs/mwas/lib/python3.11/asyncio/events.py", line 80, in _run
    self._context.run(self._callback, *self._args)
  File "/home/naglemi/miniconda3/envs/mwas/lib/python3.11/site-packages/tornado/platform/asyncio.py", line 192, in _handle_events
    handler_func(fileobj, events)
  File "/home/naglemi/miniconda3/envs/mwas/lib/python3.11/site-packages/terminado/management.py", line 252, in pty_read
    client.on_pty_read(s)
  File "/home/naglemi/miniconda3/envs/mwas/lib/python3.11/site-packages/terminado/websocket.py", line 73, in on_pty_read
    self.send_json_message(["stdout", text])
  File "/home/naglemi/miniconda3/envs/mwas/lib/python3.11/site-packages/terminado/websocket.py", line 77, in send_json_message
    self.write_message(json_msg)
  File "/home/naglemi/miniconda3/envs/mwas/lib/python3.11/site-packages/jupyter_server_terminals/handlers.py", line 57, in write_message
    super().write_message(message, binary=binary)
  File "/home/naglemi/miniconda3/envs/mwas/lib/python3.11/site-packages/tornado/websocket.py", line 331, in write_message
    raise WebSocketClosedError()
tornado.websocket.WebSocketClosedError
Exception in callback BaseAsyncIOLoop._handle_events(18, 1)
handle: <Handle BaseAsyncIOLoop._handle_events(18, 1)>
Traceback (most recent call last):
  File "/home/naglemi/miniconda3/envs/mwas/lib/python3.11/asyncio/events.py", line 80, in _run
    self._context.run(self._callback, *self._args)
  File "/home/naglemi/miniconda3/envs/mwas/lib/python3.11/site-packages/tornado/platform/asyncio.py", line 192, in _handle_events
    handler_func(fileobj, events)
  File "/home/naglemi/miniconda3/envs/mwas/lib/python3.11/site-packages/terminado/management.py", line 252, in pty_read
    client.on_pty_read(s)
  File "/home/naglemi/miniconda3/envs/mwas/lib/python3.11/site-packages/terminado/websocket.py", line 73, in on_pty_read
    self.send_json_message(["stdout", text])
  File "/home/naglemi/miniconda3/envs/mwas/lib/python3.11/site-packages/terminado/websocket.py", line 77, in send_json_message
    self.write_message(json_msg)
  File "/home/naglemi/miniconda3/envs/mwas/lib/python3.11/site-packages/jupyter_server_terminals/handlers.py", line 57, in write_message
    super().write_message(message, binary=binary)
  File "/home/naglemi/miniconda3/envs/mwas/lib/python3.11/site-packages/tornado/websocket.py", line 331, in write_message
    raise WebSocketClosedError()
tornado.websocket.WebSocketClosedError
Exception in callback BaseAsyncIOLoop._handle_events(18, 1)
handle: <Handle BaseAsyncIOLoop._handle_events(18, 1)>
Traceback (most recent call last):
  File "/home/naglemi/miniconda3/envs/mwas/lib/python3.11/asyncio/events.py", line 80, in _run
    self._context.run(self._callback, *self._args)
  File "/home/naglemi/miniconda3/envs/mwas/lib/python3.11/site-packages/tornado/platform/asyncio.py", line 192, in _handle_events
    handler_func(fileobj, events)
  File "/home/naglemi/miniconda3/envs/mwas/lib/python3.11/site-packages/terminado/management.py", line 252, in pty_read
    client.on_pty_read(s)
  File "/home/naglemi/miniconda3/envs/mwas/lib/python3.11/site-packages/terminado/websocket.py", line 73, in on_pty_read
    self.send_json_message(["stdout", text])
  File "/home/naglemi/miniconda3/envs/mwas/lib/python3.11/site-packages/terminado/websocket.py", line 77, in send_json_message
    self.write_message(json_msg)
  File "/home/naglemi/miniconda3/envs/mwas/lib/python3.11/site-packages/jupyter_server_terminals/handlers.py", line 57, in write_message
    super().write_message(message, binary=binary)
  File "/home/naglemi/miniconda3/envs/mwas/lib/python3.11/site-packages/tornado/websocket.py", line 331, in write_message
    raise WebSocketClosedError()
tornado.websocket.WebSocketClosedError
Exception in callback BaseAsyncIOLoop._handle_events(18, 1)
handle: <Handle BaseAsyncIOLoop._handle_events(18, 1)>
Traceback (most recent call last):
  File "/home/naglemi/miniconda3/envs/mwas/lib/python3.11/asyncio/events.py", line 80, in _run
    self._context.run(self._callback, *self._args)
  File "/home/naglemi/miniconda3/envs/mwas/lib/python3.11/site-packages/tornado/platform/asyncio.py", line 192, in _handle_events
    handler_func(fileobj, events)
  File "/home/naglemi/miniconda3/envs/mwas/lib/python3.11/site-packages/terminado/management.py", line 252, in pty_read
    client.on_pty_read(s)
  File "/home/naglemi/miniconda3/envs/mwas/lib/python3.11/site-packages/terminado/websocket.py", line 73, in on_pty_read
    self.send_json_message(["stdout", text])
  File "/home/naglemi/miniconda3/envs/mwas/lib/python3.11/site-packages/terminado/websocket.py", line 77, in send_json_message
    self.write_message(json_msg)
  File "/home/naglemi/miniconda3/envs/mwas/lib/python3.11/site-packages/jupyter_server_terminals/handlers.py", line 57, in write_message
    super().write_message(message, binary=binary)
  File "/home/naglemi/miniconda3/envs/mwas/lib/python3.11/site-packages/tornado/websocket.py", line 331, in write_message
    raise WebSocketClosedError()
tornado.websocket.WebSocketClosedError
Exception in callback BaseAsyncIOLoop._handle_events(17, 1)
handle: <Handle BaseAsyncIOLoop._handle_events(17, 1)>
Traceback (most recent call last):
  File "/home/naglemi/miniconda3/envs/mwas/lib/python3.11/asyncio/events.py", line 80, in _run
    self._context.run(self._callback, *self._args)
  File "/home/naglemi/miniconda3/envs/mwas/lib/python3.11/site-packages/tornado/platform/asyncio.py", line 192, in _handle_events
    handler_func(fileobj, events)
  File "/home/naglemi/miniconda3/envs/mwas/lib/python3.11/site-packages/terminado/management.py", line 252, in pty_read
    client.on_pty_read(s)
  File "/home/naglemi/miniconda3/envs/mwas/lib/python3.11/site-packages/terminado/websocket.py", line 73, in on_pty_read
    self.send_json_message(["stdout", text])
  File "/home/naglemi/miniconda3/envs/mwas/lib/python3.11/site-packages/terminado/websocket.py", line 77, in send_json_message
    self.write_message(json_msg)
  File "/home/naglemi/miniconda3/envs/mwas/lib/python3.11/site-packages/jupyter_server_terminals/handlers.py", line 57, in write_message
    super().write_message(message, binary=binary)
  File "/home/naglemi/miniconda3/envs/mwas/lib/python3.11/site-packages/tornado/websocket.py", line 331, in write_message
    raise WebSocketClosedError()
tornado.websocket.WebSocketClosedError
Exception in callback BaseAsyncIOLoop._handle_events(17, 1)
handle: <Handle BaseAsyncIOLoop._handle_events(17, 1)>
Traceback (most recent call last):
  File "/home/naglemi/miniconda3/envs/mwas/lib/python3.11/asyncio/events.py", line 80, in _run
    self._context.run(self._callback, *self._args)
  File "/home/naglemi/miniconda3/envs/mwas/lib/python3.11/site-packages/tornado/platform/asyncio.py", line 192, in _handle_events
    handler_func(fileobj, events)
  File "/home/naglemi/miniconda3/envs/mwas/lib/python3.11/site-packages/terminado/management.py", line 252, in pty_read
    client.on_pty_read(s)
  File "/home/naglemi/miniconda3/envs/mwas/lib/python3.11/site-packages/terminado/websocket.py", line 73, in on_pty_read
    self.send_json_message(["stdout", text])
  File "/home/naglemi/miniconda3/envs/mwas/lib/python3.11/site-packages/terminado/websocket.py", line 77, in send_json_message
    self.write_message(json_msg)
  File "/home/naglemi/miniconda3/envs/mwas/lib/python3.11/site-packages/jupyter_server_terminals/handlers.py", line 57, in write_message
    super().write_message(message, binary=binary)
  File "/home/naglemi/miniconda3/envs/mwas/lib/python3.11/site-packages/tornado/websocket.py", line 331, in write_message
    raise WebSocketClosedError()
tornado.websocket.WebSocketClosedError
Exception in callback BaseAsyncIOLoop._handle_events(17, 1)
handle: <Handle BaseAsyncIOLoop._handle_events(17, 1)>
Traceback (most recent call last):
  File "/home/naglemi/miniconda3/envs/mwas/lib/python3.11/asyncio/events.py", line 80, in _run
    self._context.run(self._callback, *self._args)
  File "/home/naglemi/miniconda3/envs/mwas/lib/python3.11/site-packages/tornado/platform/asyncio.py", line 192, in _handle_events
    handler_func(fileobj, events)
  File "/home/naglemi/miniconda3/envs/mwas/lib/python3.11/site-packages/terminado/management.py", line 252, in pty_read
    client.on_pty_read(s)
  File "/home/naglemi/miniconda3/envs/mwas/lib/python3.11/site-packages/terminado/websocket.py", line 73, in on_pty_read
    self.send_json_message(["stdout", text])
  File "/home/naglemi/miniconda3/envs/mwas/lib/python3.11/site-packages/terminado/websocket.py", line 77, in send_json_message
    self.write_message(json_msg)
  File "/home/naglemi/miniconda3/envs/mwas/lib/python3.11/site-packages/jupyter_server_terminals/handlers.py", line 57, in write_message
    super().write_message(message, binary=binary)
  File "/home/naglemi/miniconda3/envs/mwas/lib/python3.11/site-packages/tornado/websocket.py", line 331, in write_message
    raise WebSocketClosedError()
tornado.websocket.WebSocketClosedError
Exception in callback BaseAsyncIOLoop._handle_events(18, 1)
handle: <Handle BaseAsyncIOLoop._handle_events(18, 1)>
Traceback (most recent call last):
  File "/home/naglemi/miniconda3/envs/mwas/lib/python3.11/asyncio/events.py", line 80, in _run
    self._context.run(self._callback, *self._args)
  File "/home/naglemi/miniconda3/envs/mwas/lib/python3.11/site-packages/tornado/platform/asyncio.py", line 192, in _handle_events
    handler_func(fileobj, events)
  File "/home/naglemi/miniconda3/envs/mwas/lib/python3.11/site-packages/terminado/management.py", line 252, in pty_read
    client.on_pty_read(s)
  File "/home/naglemi/miniconda3/envs/mwas/lib/python3.11/site-packages/terminado/websocket.py", line 73, in on_pty_read
    self.send_json_message(["stdout", text])
  File "/home/naglemi/miniconda3/envs/mwas/lib/python3.11/site-packages/terminado/websocket.py", line 77, in send_json_message
    self.write_message(json_msg)
  File "/home/naglemi/miniconda3/envs/mwas/lib/python3.11/site-packages/jupyter_server_terminals/handlers.py", line 57, in write_message
    super().write_message(message, binary=binary)
  File "/home/naglemi/miniconda3/envs/mwas/lib/python3.11/site-packages/tornado/websocket.py", line 331, in write_message
    raise WebSocketClosedError()
tornado.websocket.WebSocketClosedError
Exception in callback BaseAsyncIOLoop._handle_events(18, 1)
handle: <Handle BaseAsyncIOLoop._handle_events(18, 1)>
Traceback (most recent call last):
  File "/home/naglemi/miniconda3/envs/mwas/lib/python3.11/asyncio/events.py", line 80, in _run
    self._context.run(self._callback, *self._args)
  File "/home/naglemi/miniconda3/envs/mwas/lib/python3.11/site-packages/tornado/platform/asyncio.py", line 192, in _handle_events
    handler_func(fileobj, events)
  File "/home/naglemi/miniconda3/envs/mwas/lib/python3.11/site-packages/terminado/management.py", line 252, in pty_read
    client.on_pty_read(s)
  File "/home/naglemi/miniconda3/envs/mwas/lib/python3.11/site-packages/terminado/websocket.py", line 73, in on_pty_read
    self.send_json_message(["stdout", text])
  File "/home/naglemi/miniconda3/envs/mwas/lib/python3.11/site-packages/terminado/websocket.py", line 77, in send_json_message
    self.write_message(json_msg)
  File "/home/naglemi/miniconda3/envs/mwas/lib/python3.11/site-packages/jupyter_server_terminals/handlers.py", line 57, in write_message
    super().write_message(message, binary=binary)
  File "/home/naglemi/miniconda3/envs/mwas/lib/python3.11/site-packages/tornado/websocket.py", line 331, in write_message
    raise WebSocketClosedError()
tornado.websocket.WebSocketClosedError
[I 2024-06-27 11:49:59.384 ServerApp] Connecting to kernel b42a0e13-4e2b-418f-bd0b-7a7960e6ba08.
[I 2024-06-27 11:49:59.787 ServerApp] Starting buffering for b42a0e13-4e2b-418f-bd0b-7a7960e6ba08:961fee02-bb6c-49e7-9069-733d4560756a
[W 2024-06-27 11:49:59.818 LabApp] Could not determine jupyterlab build status without nodejs
[I 2024-06-27 11:50:08.376 ServerApp] Connecting to kernel b42a0e13-4e2b-418f-bd0b-7a7960e6ba08.
[I 2024-06-27 11:52:05.291 ServerApp] Saving file at /scripts/18_overlap_risk_loci_mwas_gwas.ipynb
[I 2024-06-27 11:54:07.403 ServerApp] Saving file at /scripts/18_overlap_risk_loci_mwas_gwas.ipynb
[I 2024-06-27 12:00:08.591 ServerApp] Saving file at /scripts/18_overlap_risk_loci_mwas_gwas.ipynb
[I 2024-06-27 12:04:09.477 ServerApp] Saving file at /scripts/18_overlap_risk_loci_mwas_gwas.ipynb
[I 2024-06-27 12:06:11.497 ServerApp] Saving file at /scripts/18_overlap_risk_loci_mwas_gwas.ipynb
[I 2024-06-27 12:08:16.190 ServerApp] Saving file at /scripts/18_overlap_risk_loci_mwas_gwas.ipynb
[I 2024-06-27 12:10:17.027 ServerApp] Saving file at /scripts/18_overlap_risk_loci_mwas_gwas.ipynb
[I 2024-06-27 12:12:19.036 ServerApp] Saving file at /scripts/18_overlap_risk_loci_mwas_gwas.ipynb
[W 2024-06-27 12:17:03.282 TerminalsExtensionApp] WebSocket ping timeout after 119742 ms.
[W 2024-06-27 12:17:03.289 TerminalsExtensionApp] WebSocket ping timeout after 119749 ms.
[W 2024-06-27 12:17:03.292 TerminalsExtensionApp] WebSocket ping timeout after 119752 ms.
Exception in callback BaseAsyncIOLoop._handle_events(18, 1)
handle: <Handle BaseAsyncIOLoop._handle_events(18, 1)>
Traceback (most recent call last):
  File "/home/naglemi/miniconda3/envs/mwas/lib/python3.11/asyncio/events.py", line 80, in _run
    self._context.run(self._callback, *self._args)
  File "/home/naglemi/miniconda3/envs/mwas/lib/python3.11/site-packages/tornado/platform/asyncio.py", line 192, in _handle_events
    handler_func(fileobj, events)
  File "/home/naglemi/miniconda3/envs/mwas/lib/python3.11/site-packages/terminado/management.py", line 252, in pty_read
    client.on_pty_read(s)
  File "/home/naglemi/miniconda3/envs/mwas/lib/python3.11/site-packages/terminado/websocket.py", line 73, in on_pty_read
    self.send_json_message(["stdout", text])
  File "/home/naglemi/miniconda3/envs/mwas/lib/python3.11/site-packages/terminado/websocket.py", line 77, in send_json_message
    self.write_message(json_msg)
  File "/home/naglemi/miniconda3/envs/mwas/lib/python3.11/site-packages/jupyter_server_terminals/handlers.py", line 57, in write_message
    super().write_message(message, binary=binary)
  File "/home/naglemi/miniconda3/envs/mwas/lib/python3.11/site-packages/tornado/websocket.py", line 331, in write_message
    raise WebSocketClosedError()
tornado.websocket.WebSocketClosedError
Exception in callback BaseAsyncIOLoop._handle_events(18, 1)
handle: <Handle BaseAsyncIOLoop._handle_events(18, 1)>
Traceback (most recent call last):
  File "/home/naglemi/miniconda3/envs/mwas/lib/python3.11/asyncio/events.py", line 80, in _run
    self._context.run(self._callback, *self._args)
  File "/home/naglemi/miniconda3/envs/mwas/lib/python3.11/site-packages/tornado/platform/asyncio.py", line 192, in _handle_events
    handler_func(fileobj, events)
  File "/home/naglemi/miniconda3/envs/mwas/lib/python3.11/site-packages/terminado/management.py", line 252, in pty_read
    client.on_pty_read(s)
  File "/home/naglemi/miniconda3/envs/mwas/lib/python3.11/site-packages/terminado/websocket.py", line 73, in on_pty_read
    self.send_json_message(["stdout", text])
  File "/home/naglemi/miniconda3/envs/mwas/lib/python3.11/site-packages/terminado/websocket.py", line 77, in send_json_message
    self.write_message(json_msg)
  File "/home/naglemi/miniconda3/envs/mwas/lib/python3.11/site-packages/jupyter_server_terminals/handlers.py", line 57, in write_message
    super().write_message(message, binary=binary)
  File "/home/naglemi/miniconda3/envs/mwas/lib/python3.11/site-packages/tornado/websocket.py", line 331, in write_message
    raise WebSocketClosedError()
tornado.websocket.WebSocketClosedError
Exception in callback BaseAsyncIOLoop._handle_events(17, 1)
handle: <Handle BaseAsyncIOLoop._handle_events(17, 1)>
Traceback (most recent call last):
  File "/home/naglemi/miniconda3/envs/mwas/lib/python3.11/asyncio/events.py", line 80, in _run
    self._context.run(self._callback, *self._args)
  File "/home/naglemi/miniconda3/envs/mwas/lib/python3.11/site-packages/tornado/platform/asyncio.py", line 192, in _handle_events
    handler_func(fileobj, events)
  File "/home/naglemi/miniconda3/envs/mwas/lib/python3.11/site-packages/terminado/management.py", line 252, in pty_read
    client.on_pty_read(s)
  File "/home/naglemi/miniconda3/envs/mwas/lib/python3.11/site-packages/terminado/websocket.py", line 73, in on_pty_read
    self.send_json_message(["stdout", text])
  File "/home/naglemi/miniconda3/envs/mwas/lib/python3.11/site-packages/terminado/websocket.py", line 77, in send_json_message
    self.write_message(json_msg)
  File "/home/naglemi/miniconda3/envs/mwas/lib/python3.11/site-packages/jupyter_server_terminals/handlers.py", line 57, in write_message
    super().write_message(message, binary=binary)
  File "/home/naglemi/miniconda3/envs/mwas/lib/python3.11/site-packages/tornado/websocket.py", line 331, in write_message
    raise WebSocketClosedError()
tornado.websocket.WebSocketClosedError
Exception in callback BaseAsyncIOLoop._handle_events(17, 1)
handle: <Handle BaseAsyncIOLoop._handle_events(17, 1)>
Traceback (most recent call last):
  File "/home/naglemi/miniconda3/envs/mwas/lib/python3.11/asyncio/events.py", line 80, in _run
    self._context.run(self._callback, *self._args)
  File "/home/naglemi/miniconda3/envs/mwas/lib/python3.11/site-packages/tornado/platform/asyncio.py", line 192, in _handle_events
    handler_func(fileobj, events)
  File "/home/naglemi/miniconda3/envs/mwas/lib/python3.11/site-packages/terminado/management.py", line 252, in pty_read
    client.on_pty_read(s)
  File "/home/naglemi/miniconda3/envs/mwas/lib/python3.11/site-packages/terminado/websocket.py", line 73, in on_pty_read
    self.send_json_message(["stdout", text])
  File "/home/naglemi/miniconda3/envs/mwas/lib/python3.11/site-packages/terminado/websocket.py", line 77, in send_json_message
    self.write_message(json_msg)
  File "/home/naglemi/miniconda3/envs/mwas/lib/python3.11/site-packages/jupyter_server_terminals/handlers.py", line 57, in write_message
    super().write_message(message, binary=binary)
  File "/home/naglemi/miniconda3/envs/mwas/lib/python3.11/site-packages/tornado/websocket.py", line 331, in write_message
    raise WebSocketClosedError()
tornado.websocket.WebSocketClosedError
Exception in callback BaseAsyncIOLoop._handle_events(17, 1)
handle: <Handle BaseAsyncIOLoop._handle_events(17, 1)>
Traceback (most recent call last):
  File "/home/naglemi/miniconda3/envs/mwas/lib/python3.11/asyncio/events.py", line 80, in _run
    self._context.run(self._callback, *self._args)
  File "/home/naglemi/miniconda3/envs/mwas/lib/python3.11/site-packages/tornado/platform/asyncio.py", line 192, in _handle_events
    handler_func(fileobj, events)
  File "/home/naglemi/miniconda3/envs/mwas/lib/python3.11/site-packages/terminado/management.py", line 252, in pty_read
    client.on_pty_read(s)
  File "/home/naglemi/miniconda3/envs/mwas/lib/python3.11/site-packages/terminado/websocket.py", line 73, in on_pty_read
    self.send_json_message(["stdout", text])
  File "/home/naglemi/miniconda3/envs/mwas/lib/python3.11/site-packages/terminado/websocket.py", line 77, in send_json_message
    self.write_message(json_msg)
  File "/home/naglemi/miniconda3/envs/mwas/lib/python3.11/site-packages/jupyter_server_terminals/handlers.py", line 57, in write_message
    super().write_message(message, binary=binary)
  File "/home/naglemi/miniconda3/envs/mwas/lib/python3.11/site-packages/tornado/websocket.py", line 331, in write_message
    raise WebSocketClosedError()
tornado.websocket.WebSocketClosedError
Exception in callback BaseAsyncIOLoop._handle_events(18, 1)
handle: <Handle BaseAsyncIOLoop._handle_events(18, 1)>
Traceback (most recent call last):
  File "/home/naglemi/miniconda3/envs/mwas/lib/python3.11/asyncio/events.py", line 80, in _run
    self._context.run(self._callback, *self._args)
  File "/home/naglemi/miniconda3/envs/mwas/lib/python3.11/site-packages/tornado/platform/asyncio.py", line 192, in _handle_events
    handler_func(fileobj, events)
  File "/home/naglemi/miniconda3/envs/mwas/lib/python3.11/site-packages/terminado/management.py", line 252, in pty_read
    client.on_pty_read(s)
  File "/home/naglemi/miniconda3/envs/mwas/lib/python3.11/site-packages/terminado/websocket.py", line 73, in on_pty_read
    self.send_json_message(["stdout", text])
  File "/home/naglemi/miniconda3/envs/mwas/lib/python3.11/site-packages/terminado/websocket.py", line 77, in send_json_message
    self.write_message(json_msg)
  File "/home/naglemi/miniconda3/envs/mwas/lib/python3.11/site-packages/jupyter_server_terminals/handlers.py", line 57, in write_message
    super().write_message(message, binary=binary)
  File "/home/naglemi/miniconda3/envs/mwas/lib/python3.11/site-packages/tornado/websocket.py", line 331, in write_message
    raise WebSocketClosedError()
tornado.websocket.WebSocketClosedError
Exception in callback BaseAsyncIOLoop._handle_events(18, 1)
handle: <Handle BaseAsyncIOLoop._handle_events(18, 1)>
Traceback (most recent call last):
  File "/home/naglemi/miniconda3/envs/mwas/lib/python3.11/asyncio/events.py", line 80, in _run
    self._context.run(self._callback, *self._args)
  File "/home/naglemi/miniconda3/envs/mwas/lib/python3.11/site-packages/tornado/platform/asyncio.py", line 192, in _handle_events
    handler_func(fileobj, events)
  File "/home/naglemi/miniconda3/envs/mwas/lib/python3.11/site-packages/terminado/management.py", line 252, in pty_read
    client.on_pty_read(s)
  File "/home/naglemi/miniconda3/envs/mwas/lib/python3.11/site-packages/terminado/websocket.py", line 73, in on_pty_read
    self.send_json_message(["stdout", text])
  File "/home/naglemi/miniconda3/envs/mwas/lib/python3.11/site-packages/terminado/websocket.py", line 77, in send_json_message
    self.write_message(json_msg)
  File "/home/naglemi/miniconda3/envs/mwas/lib/python3.11/site-packages/jupyter_server_terminals/handlers.py", line 57, in write_message
    super().write_message(message, binary=binary)
  File "/home/naglemi/miniconda3/envs/mwas/lib/python3.11/site-packages/tornado/websocket.py", line 331, in write_message
    raise WebSocketClosedError()
tornado.websocket.WebSocketClosedError
Exception in callback BaseAsyncIOLoop._handle_events(18, 1)
handle: <Handle BaseAsyncIOLoop._handle_events(18, 1)>
Traceback (most recent call last):
  File "/home/naglemi/miniconda3/envs/mwas/lib/python3.11/asyncio/events.py", line 80, in _run
    self._context.run(self._callback, *self._args)
  File "/home/naglemi/miniconda3/envs/mwas/lib/python3.11/site-packages/tornado/platform/asyncio.py", line 192, in _handle_events
    handler_func(fileobj, events)
  File "/home/naglemi/miniconda3/envs/mwas/lib/python3.11/site-packages/terminado/management.py", line 252, in pty_read
    client.on_pty_read(s)
  File "/home/naglemi/miniconda3/envs/mwas/lib/python3.11/site-packages/terminado/websocket.py", line 73, in on_pty_read
    self.send_json_message(["stdout", text])
  File "/home/naglemi/miniconda3/envs/mwas/lib/python3.11/site-packages/terminado/websocket.py", line 77, in send_json_message
    self.write_message(json_msg)
  File "/home/naglemi/miniconda3/envs/mwas/lib/python3.11/site-packages/jupyter_server_terminals/handlers.py", line 57, in write_message
    super().write_message(message, binary=binary)
  File "/home/naglemi/miniconda3/envs/mwas/lib/python3.11/site-packages/tornado/websocket.py", line 331, in write_message
    raise WebSocketClosedError()
tornado.websocket.WebSocketClosedError
Exception in callback BaseAsyncIOLoop._handle_events(18, 1)
handle: <Handle BaseAsyncIOLoop._handle_events(18, 1)>
Traceback (most recent call last):
  File "/home/naglemi/miniconda3/envs/mwas/lib/python3.11/asyncio/events.py", line 80, in _run
    self._context.run(self._callback, *self._args)
  File "/home/naglemi/miniconda3/envs/mwas/lib/python3.11/site-packages/tornado/platform/asyncio.py", line 192, in _handle_events
    handler_func(fileobj, events)
  File "/home/naglemi/miniconda3/envs/mwas/lib/python3.11/site-packages/terminado/management.py", line 252, in pty_read
    client.on_pty_read(s)
  File "/home/naglemi/miniconda3/envs/mwas/lib/python3.11/site-packages/terminado/websocket.py", line 73, in on_pty_read
    self.send_json_message(["stdout", text])
  File "/home/naglemi/miniconda3/envs/mwas/lib/python3.11/site-packages/terminado/websocket.py", line 77, in send_json_message
    self.write_message(json_msg)
  File "/home/naglemi/miniconda3/envs/mwas/lib/python3.11/site-packages/jupyter_server_terminals/handlers.py", line 57, in write_message
    super().write_message(message, binary=binary)
  File "/home/naglemi/miniconda3/envs/mwas/lib/python3.11/site-packages/tornado/websocket.py", line 331, in write_message
    raise WebSocketClosedError()
tornado.websocket.WebSocketClosedError
Exception in callback BaseAsyncIOLoop._handle_events(17, 1)
handle: <Handle BaseAsyncIOLoop._handle_events(17, 1)>
Traceback (most recent call last):
  File "/home/naglemi/miniconda3/envs/mwas/lib/python3.11/asyncio/events.py", line 80, in _run
    self._context.run(self._callback, *self._args)
  File "/home/naglemi/miniconda3/envs/mwas/lib/python3.11/site-packages/tornado/platform/asyncio.py", line 192, in _handle_events
    handler_func(fileobj, events)
  File "/home/naglemi/miniconda3/envs/mwas/lib/python3.11/site-packages/terminado/management.py", line 252, in pty_read
    client.on_pty_read(s)
  File "/home/naglemi/miniconda3/envs/mwas/lib/python3.11/site-packages/terminado/websocket.py", line 73, in on_pty_read
    self.send_json_message(["stdout", text])
  File "/home/naglemi/miniconda3/envs/mwas/lib/python3.11/site-packages/terminado/websocket.py", line 77, in send_json_message
    self.write_message(json_msg)
  File "/home/naglemi/miniconda3/envs/mwas/lib/python3.11/site-packages/jupyter_server_terminals/handlers.py", line 57, in write_message
    super().write_message(message, binary=binary)
  File "/home/naglemi/miniconda3/envs/mwas/lib/python3.11/site-packages/tornado/websocket.py", line 331, in write_message
    raise WebSocketClosedError()
tornado.websocket.WebSocketClosedError
Exception in callback BaseAsyncIOLoop._handle_events(17, 1)
handle: <Handle BaseAsyncIOLoop._handle_events(17, 1)>
Traceback (most recent call last):
  File "/home/naglemi/miniconda3/envs/mwas/lib/python3.11/asyncio/events.py", line 80, in _run
    self._context.run(self._callback, *self._args)
  File "/home/naglemi/miniconda3/envs/mwas/lib/python3.11/site-packages/tornado/platform/asyncio.py", line 192, in _handle_events
    handler_func(fileobj, events)
  File "/home/naglemi/miniconda3/envs/mwas/lib/python3.11/site-packages/terminado/management.py", line 252, in pty_read
    client.on_pty_read(s)
  File "/home/naglemi/miniconda3/envs/mwas/lib/python3.11/site-packages/terminado/websocket.py", line 73, in on_pty_read
    self.send_json_message(["stdout", text])
  File "/home/naglemi/miniconda3/envs/mwas/lib/python3.11/site-packages/terminado/websocket.py", line 77, in send_json_message
    self.write_message(json_msg)
  File "/home/naglemi/miniconda3/envs/mwas/lib/python3.11/site-packages/jupyter_server_terminals/handlers.py", line 57, in write_message
    super().write_message(message, binary=binary)
  File "/home/naglemi/miniconda3/envs/mwas/lib/python3.11/site-packages/tornado/websocket.py", line 331, in write_message
    raise WebSocketClosedError()
tornado.websocket.WebSocketClosedError
Exception in callback BaseAsyncIOLoop._handle_events(17, 1)
handle: <Handle BaseAsyncIOLoop._handle_events(17, 1)>
Traceback (most recent call last):
  File "/home/naglemi/miniconda3/envs/mwas/lib/python3.11/asyncio/events.py", line 80, in _run
    self._context.run(self._callback, *self._args)
  File "/home/naglemi/miniconda3/envs/mwas/lib/python3.11/site-packages/tornado/platform/asyncio.py", line 192, in _handle_events
    handler_func(fileobj, events)
  File "/home/naglemi/miniconda3/envs/mwas/lib/python3.11/site-packages/terminado/management.py", line 252, in pty_read
    client.on_pty_read(s)
  File "/home/naglemi/miniconda3/envs/mwas/lib/python3.11/site-packages/terminado/websocket.py", line 73, in on_pty_read
    self.send_json_message(["stdout", text])
  File "/home/naglemi/miniconda3/envs/mwas/lib/python3.11/site-packages/terminado/websocket.py", line 77, in send_json_message
    self.write_message(json_msg)
  File "/home/naglemi/miniconda3/envs/mwas/lib/python3.11/site-packages/jupyter_server_terminals/handlers.py", line 57, in write_message
    super().write_message(message, binary=binary)
  File "/home/naglemi/miniconda3/envs/mwas/lib/python3.11/site-packages/tornado/websocket.py", line 331, in write_message
    raise WebSocketClosedError()
tornado.websocket.WebSocketClosedError
Exception in callback BaseAsyncIOLoop._handle_events(18, 1)
handle: <Handle BaseAsyncIOLoop._handle_events(18, 1)>
Traceback (most recent call last):
  File "/home/naglemi/miniconda3/envs/mwas/lib/python3.11/asyncio/events.py", line 80, in _run
    self._context.run(self._callback, *self._args)
  File "/home/naglemi/miniconda3/envs/mwas/lib/python3.11/site-packages/tornado/platform/asyncio.py", line 192, in _handle_events
    handler_func(fileobj, events)
  File "/home/naglemi/miniconda3/envs/mwas/lib/python3.11/site-packages/terminado/management.py", line 252, in pty_read
    client.on_pty_read(s)
  File "/home/naglemi/miniconda3/envs/mwas/lib/python3.11/site-packages/terminado/websocket.py", line 73, in on_pty_read
    self.send_json_message(["stdout", text])
  File "/home/naglemi/miniconda3/envs/mwas/lib/python3.11/site-packages/terminado/websocket.py", line 77, in send_json_message
    self.write_message(json_msg)
  File "/home/naglemi/miniconda3/envs/mwas/lib/python3.11/site-packages/jupyter_server_terminals/handlers.py", line 57, in write_message
    super().write_message(message, binary=binary)
  File "/home/naglemi/miniconda3/envs/mwas/lib/python3.11/site-packages/tornado/websocket.py", line 331, in write_message
    raise WebSocketClosedError()
tornado.websocket.WebSocketClosedError
Exception in callback BaseAsyncIOLoop._handle_events(18, 1)
handle: <Handle BaseAsyncIOLoop._handle_events(18, 1)>
Traceback (most recent call last):
  File "/home/naglemi/miniconda3/envs/mwas/lib/python3.11/asyncio/events.py", line 80, in _run
    self._context.run(self._callback, *self._args)
  File "/home/naglemi/miniconda3/envs/mwas/lib/python3.11/site-packages/tornado/platform/asyncio.py", line 192, in _handle_events
    handler_func(fileobj, events)
  File "/home/naglemi/miniconda3/envs/mwas/lib/python3.11/site-packages/terminado/management.py", line 252, in pty_read
    client.on_pty_read(s)
  File "/home/naglemi/miniconda3/envs/mwas/lib/python3.11/site-packages/terminado/websocket.py", line 73, in on_pty_read
    self.send_json_message(["stdout", text])
  File "/home/naglemi/miniconda3/envs/mwas/lib/python3.11/site-packages/terminado/websocket.py", line 77, in send_json_message
    self.write_message(json_msg)
  File "/home/naglemi/miniconda3/envs/mwas/lib/python3.11/site-packages/jupyter_server_terminals/handlers.py", line 57, in write_message
    super().write_message(message, binary=binary)
  File "/home/naglemi/miniconda3/envs/mwas/lib/python3.11/site-packages/tornado/websocket.py", line 331, in write_message
    raise WebSocketClosedError()
tornado.websocket.WebSocketClosedError
[W 2024-06-27 12:17:08.377 ServerApp] WebSocket ping timeout after 119719 ms.
[I 2024-06-27 12:17:13.378 ServerApp] Starting buffering for b42a0e13-4e2b-418f-bd0b-7a7960e6ba08:15cdb87b-d08c-41ee-afe3-85ec750a5918
[I 2024-06-28 10:44:47.299 ServerApp] 302 GET / (@127.0.0.1) 0.47ms
[W 2024-06-28 10:44:50.582 LabApp] Could not determine jupyterlab build status without nodejs
[I 2024-06-28 10:44:50.672 ServerApp] Connecting to kernel b42a0e13-4e2b-418f-bd0b-7a7960e6ba08.
[I 2024-06-28 10:44:50.844 ServerApp] Starting buffering for b42a0e13-4e2b-418f-bd0b-7a7960e6ba08:32edc388-f211-4713-a1d8-8b25afc069a9
[I 2024-06-28 10:44:53.180 ServerApp] Connecting to kernel b42a0e13-4e2b-418f-bd0b-7a7960e6ba08.
[I 2024-06-28 10:44:55.183 ServerApp] Connecting to kernel b42a0e13-4e2b-418f-bd0b-7a7960e6ba08.
[I 2024-06-28 10:46:52.863 ServerApp] Saving file at /scripts/18_overlap_risk_loci_mwas_gwas.ipynb
[I 2024-06-28 10:48:53.647 ServerApp] Saving file at /scripts/18_overlap_risk_loci_mwas_gwas.ipynb
[I 2024-06-28 10:50:54.037 ServerApp] Saving file at /scripts/18_overlap_risk_loci_mwas_gwas.ipynb
[W 2024-06-28 10:50:55.400 ServerApp] delete /scripts/Untitled13.ipynb
[W 2024-06-28 10:50:55.401 ServerApp] 400 DELETE /api/contents/scripts/Untitled13.ipynb?1719597055362 (127.0.0.1): send2trash f`1ailed: [Errno 13] Permission denied: b'/expanse/lustre/projects/.Trash-525019'
[W 2024-06-28 10:50:55.401 ServerApp] wrote error: "send2trash f`1ailed: [Errno 13] Permission denied: b'/expanse/lustre/projects/.Trash-525019'"
    Traceback (most recent call last):
      File "/home/naglemi/miniconda3/envs/mwas/lib/python3.11/site-packages/send2trash/plat_other.py", line 158, in find_ext_volume_fallback_trash
        check_create(trash_dir)
      File "/home/naglemi/miniconda3/envs/mwas/lib/python3.11/site-packages/send2trash/plat_other.py", line 96, in check_create
        os.makedirs(dir, 0o700)
      File "<frozen os>", line 225, in makedirs
    PermissionError: [Errno 13] Permission denied: b'/expanse/lustre/projects/.Trash-525019'
    
    During handling of the above exception, another exception occurred:
    
    Traceback (most recent call last):
      File "/home/naglemi/miniconda3/envs/mwas/lib/python3.11/site-packages/jupyter_server/services/contents/filemanager.py", line 981, in delete_file
        send2trash(os_path)
      File "/home/naglemi/miniconda3/envs/mwas/lib/python3.11/site-packages/send2trash/plat_other.py", line 210, in send2trash
        dest_trash = find_ext_volume_trash(topdir)
                     ^^^^^^^^^^^^^^^^^^^^^^^^^^^^^
      File "/home/naglemi/miniconda3/envs/mwas/lib/python3.11/site-packages/send2trash/plat_other.py", line 169, in find_ext_volume_trash
        trash_dir = find_ext_volume_fallback_trash(volume_root)
                    ^^^^^^^^^^^^^^^^^^^^^^^^^^^^^^^^^^^^^^^^^^^
      File "/home/naglemi/miniconda3/envs/mwas/lib/python3.11/site-packages/send2trash/plat_other.py", line 161, in find_ext_volume_fallback_trash
        raise TrashPermissionError(e.filename)
    send2trash.exceptions.TrashPermissionError: [Errno 13] Permission denied: b'/expanse/lustre/projects/.Trash-525019'
    
    The above exception was the direct cause of the following exception:
    
    Traceback (most recent call last):
      File "/home/naglemi/miniconda3/envs/mwas/lib/python3.11/site-packages/tornado/web.py", line 1786, in _execute
        result = await result
                 ^^^^^^^^^^^^
      File "/home/naglemi/miniconda3/envs/mwas/lib/python3.11/site-packages/jupyter_server/services/contents/handlers.py", line 282, in delete
        await ensure_async(cm.delete(path))
      File "/home/naglemi/miniconda3/envs/mwas/lib/python3.11/site-packages/jupyter_core/utils/__init__.py", line 189, in ensure_async
        result = await obj
                 ^^^^^^^^^
      File "/home/naglemi/miniconda3/envs/mwas/lib/python3.11/site-packages/jupyter_server/services/contents/manager.py", line 883, in delete
        await self.delete_file(path)
      File "/home/naglemi/miniconda3/envs/mwas/lib/python3.11/site-packages/jupyter_server/services/contents/filemanager.py", line 983, in delete_file
        raise web.HTTPError(400, "send2trash f`1ailed: %s" % e) from e
    tornado.web.HTTPError: HTTP 400: Bad Request (send2trash f`1ailed: [Errno 13] Permission denied: b'/expanse/lustre/projects/.Trash-525019')
[W 2024-06-28 10:50:55.512 ServerApp] 400 DELETE /api/contents/scripts/Untitled13.ipynb?1719597055362 (3f38821adc424272adcb326f4f5b79cc@127.0.0.1) 112.39ms referer=http://localhost:8892/lab/tree/scripts/Untitled13.ipynb
[I 2024-06-28 10:51:11.232 ServerApp] Kernel started: a203def8-86bf-4d59-be3a-18228f903efc
[I 2024-06-28 10:51:14.564 ServerApp] Connecting to kernel a203def8-86bf-4d59-be3a-18228f903efc.
[I 2024-06-28 10:51:14.565 ServerApp] Connecting to kernel a203def8-86bf-4d59-be3a-18228f903efc.
[I 2024-06-28 10:51:14.579 ServerApp] Connecting to kernel a203def8-86bf-4d59-be3a-18228f903efc.
[W 2024-06-28 10:51:36.893 ServerApp] Notebook scripts/Untitled1.ipynb is not trusted
[I 2024-06-28 10:51:37.343 ServerApp] Kernel started: 3724b419-bd5b-4e5b-9753-319c0657241e
[I 2024-06-28 10:51:37.990 ServerApp] Connecting to kernel 3724b419-bd5b-4e5b-9753-319c0657241e.
[I 2024-06-28 10:51:38.972 ServerApp] Kernel started: d4978bc2-37de-45d9-a8fd-4d46ac543cd6
[I 2024-06-28 10:51:39.662 ServerApp] Connecting to kernel d4978bc2-37de-45d9-a8fd-4d46ac543cd6.
[I 2024-06-28 10:51:45.216 ServerApp] Kernel started: 6d5d0771-5ef4-458d-80e8-6832a9813154
[I 2024-06-28 10:51:45.872 ServerApp] Connecting to kernel 6d5d0771-5ef4-458d-80e8-6832a9813154.
[I 2024-06-28 10:51:48.139 ServerApp] Kernel started: c0327d0c-65e2-4518-b82a-afa95e5faa44
[I 2024-06-28 10:51:48.767 ServerApp] Connecting to kernel c0327d0c-65e2-4518-b82a-afa95e5faa44.
[I 2024-06-28 10:51:52.932 ServerApp] Kernel shutdown: c0327d0c-65e2-4518-b82a-afa95e5faa44
[W 2024-06-28 10:51:53.398 ServerApp] delete /scripts/Untitled9.ipynb
[W 2024-06-28 10:51:53.399 ServerApp] 400 DELETE /api/contents/scripts/Untitled9.ipynb?1719597113363 (127.0.0.1): send2trash f`1ailed: [Errno 13] Permission denied: b'/expanse/lustre/projects/.Trash-525019'
[W 2024-06-28 10:51:53.399 ServerApp] wrote error: "send2trash f`1ailed: [Errno 13] Permission denied: b'/expanse/lustre/projects/.Trash-525019'"
    Traceback (most recent call last):
      File "/home/naglemi/miniconda3/envs/mwas/lib/python3.11/site-packages/send2trash/plat_other.py", line 158, in find_ext_volume_fallback_trash
        check_create(trash_dir)
      File "/home/naglemi/miniconda3/envs/mwas/lib/python3.11/site-packages/send2trash/plat_other.py", line 96, in check_create
        os.makedirs(dir, 0o700)
      File "<frozen os>", line 225, in makedirs
    PermissionError: [Errno 13] Permission denied: b'/expanse/lustre/projects/.Trash-525019'
    
    During handling of the above exception, another exception occurred:
    
    Traceback (most recent call last):
      File "/home/naglemi/miniconda3/envs/mwas/lib/python3.11/site-packages/jupyter_server/services/contents/filemanager.py", line 981, in delete_file
        send2trash(os_path)
      File "/home/naglemi/miniconda3/envs/mwas/lib/python3.11/site-packages/send2trash/plat_other.py", line 210, in send2trash
        dest_trash = find_ext_volume_trash(topdir)
                     ^^^^^^^^^^^^^^^^^^^^^^^^^^^^^
      File "/home/naglemi/miniconda3/envs/mwas/lib/python3.11/site-packages/send2trash/plat_other.py", line 169, in find_ext_volume_trash
        trash_dir = find_ext_volume_fallback_trash(volume_root)
                    ^^^^^^^^^^^^^^^^^^^^^^^^^^^^^^^^^^^^^^^^^^^
      File "/home/naglemi/miniconda3/envs/mwas/lib/python3.11/site-packages/send2trash/plat_other.py", line 161, in find_ext_volume_fallback_trash
        raise TrashPermissionError(e.filename)
    send2trash.exceptions.TrashPermissionError: [Errno 13] Permission denied: b'/expanse/lustre/projects/.Trash-525019'
    
    The above exception was the direct cause of the following exception:
    
    Traceback (most recent call last):
      File "/home/naglemi/miniconda3/envs/mwas/lib/python3.11/site-packages/tornado/web.py", line 1786, in _execute
        result = await result
                 ^^^^^^^^^^^^
      File "/home/naglemi/miniconda3/envs/mwas/lib/python3.11/site-packages/jupyter_server/services/contents/handlers.py", line 282, in delete
        await ensure_async(cm.delete(path))
      File "/home/naglemi/miniconda3/envs/mwas/lib/python3.11/site-packages/jupyter_core/utils/__init__.py", line 189, in ensure_async
        result = await obj
                 ^^^^^^^^^
      File "/home/naglemi/miniconda3/envs/mwas/lib/python3.11/site-packages/jupyter_server/services/contents/manager.py", line 883, in delete
        await self.delete_file(path)
      File "/home/naglemi/miniconda3/envs/mwas/lib/python3.11/site-packages/jupyter_server/services/contents/filemanager.py", line 983, in delete_file
        raise web.HTTPError(400, "send2trash f`1ailed: %s" % e) from e
    tornado.web.HTTPError: HTTP 400: Bad Request (send2trash f`1ailed: [Errno 13] Permission denied: b'/expanse/lustre/projects/.Trash-525019')
[W 2024-06-28 10:51:53.400 ServerApp] 400 DELETE /api/contents/scripts/Untitled9.ipynb?1719597113363 (3f38821adc424272adcb326f4f5b79cc@127.0.0.1) 2.21ms referer=http://localhost:8892/lab/tree/scripts/Untitled9.ipynb
[I 2024-06-28 10:52:23.675 ServerApp] Kernel started: d2a86547-5f51-49a5-a801-06cae21fefec
[I 2024-06-28 10:52:24.325 ServerApp] Connecting to kernel d2a86547-5f51-49a5-a801-06cae21fefec.
[I 2024-06-28 10:52:28.040 ServerApp] Starting buffering for d2a86547-5f51-49a5-a801-06cae21fefec:e312a6da-d781-4477-92e6-2afe017b5dfd
[I 2024-06-28 10:52:31.114 ServerApp] Creating new notebook in /scripts
[I 2024-06-28 10:52:36.281 ServerApp] Kernel started: e70d19f9-5d73-4cab-bede-e078f4169e9f
[I 2024-06-28 10:52:36.902 ServerApp] Connecting to kernel e70d19f9-5d73-4cab-bede-e078f4169e9f.
[E 2024-06-28 10:53:46.821 LabApp] Fail to get yarn configuration. /home/naglemi/miniconda3/envs/mwas/lib/python3.11/site-packages/jupyterlab/staging/yarn.js:4
    (()=>{var Qge=Object.create;var AS=Object.defineProperty;var bge=Object.getOwnPropertyDescriptor;var Sge=Object.getOwnPropertyNames;var vge=Object.getPrototypeOf,xge=Object.prototype.hasOwnProperty;var J=(r=>typeof require<"u"?require:typeof Proxy<"u"?new Proxy(r,{get:(e,t)=>(typeof require<"u"?require:e)[t]}):r)(function(r){if(typeof require<"u")return require.apply(this,arguments);throw new Error('Dynamic require of "'+r+'" is not supported')});var Pge=(r,e)=>()=>(r&&(e=r(r=0)),e);var w=(r,e)=>()=>(e||r((e={exports:{}}).exports,e),e.exports),ut=(r,e)=>{for(var t in e)AS(r,t,{get:e[t],enumerable:!0})},Dge=(r,e,t,i)=>{if(e&&typeof e=="object"||typeof e=="function")for(let n of Sge(e))!xge.call(r,n)&&n!==t&&AS(r,n,{get:()=>e[n],enumerable:!(i=bge(e,n))||i.enumerable});return r};var Pe=(r,e,t)=>(t=r!=null?Qge(vge(r)):{},Dge(e||!r||!r.__esModule?AS(t,"default",{value:r,enumerable:!0}):t,r));var QK=w((GXe,BK)=>{BK.expor
    
    SyntaxError: Unexpected token {
        at createScript (vm.js:56:10)
        at Object.runInThisContext (vm.js:97:10)
        at Module._compile (module.js:549:28)
        at Object.Module._extensions..js (module.js:586:10)
        at Module.load (module.js:494:32)
        at tryModuleLoad (module.js:453:12)
        at Function.Module._load (module.js:445:3)
        at Module.runMain (module.js:611:10)
        at run (bootstrap_node.js:387:7)
        at startup (bootstrap_node.js:153:9)
    
[I 2024-06-28 10:53:55.148 ServerApp] Kernel shutdown: b42a0e13-4e2b-418f-bd0b-7a7960e6ba08
[I 2024-06-28 10:53:55.148 ServerApp] Kernel shutdown: a203def8-86bf-4d59-be3a-18228f903efc
[I 2024-06-28 10:53:55.149 ServerApp] Kernel shutdown: 3724b419-bd5b-4e5b-9753-319c0657241e
[I 2024-06-28 10:53:55.150 ServerApp] Kernel shutdown: d4978bc2-37de-45d9-a8fd-4d46ac543cd6
[I 2024-06-28 10:53:55.284 ServerApp] Kernel shutdown: d2a86547-5f51-49a5-a801-06cae21fefec
[I 2024-06-28 10:53:55.285 ServerApp] Kernel shutdown: 6d5d0771-5ef4-458d-80e8-6832a9813154
[I 2024-06-28 10:53:55.353 ServerApp] Kernel shutdown: e70d19f9-5d73-4cab-bede-e078f4169e9f
[I 2024-06-28 10:54:27.513 ServerApp] Kernel started: a26eb996-c01a-4b50-a73c-399030bd4afd
[I 2024-06-28 10:54:28.162 ServerApp] Connecting to kernel a26eb996-c01a-4b50-a73c-399030bd4afd.
[I 2024-06-28 10:54:32.436 ServerApp] Saving file at /scripts/19_plot.ipynb
[I 2024-06-28 10:54:42.755 ServerApp] Kernel restarted: a26eb996-c01a-4b50-a73c-399030bd4afd
[I 2024-06-28 10:54:42.830 ServerApp] Starting buffering for a26eb996-c01a-4b50-a73c-399030bd4afd:259fe5f2-e55b-426e-aae4-f95c0cafb0c7
[I 2024-06-28 10:54:42.971 ServerApp] Connecting to kernel a26eb996-c01a-4b50-a73c-399030bd4afd.
[I 2024-06-28 10:54:42.971 ServerApp] Restoring connection for a26eb996-c01a-4b50-a73c-399030bd4afd:259fe5f2-e55b-426e-aae4-f95c0cafb0c7
[I 2024-06-28 10:56:33.134 ServerApp] Saving file at /scripts/19_plot.ipynb
[I 2024-06-28 11:02:33.663 ServerApp] Saving file at /scripts/19_plot.ipynb
[I 2024-06-28 11:04:34.143 ServerApp] Saving file at /scripts/19_plot.ipynb
[I 2024-06-28 11:06:34.869 ServerApp] Saving file at /scripts/19_plot.ipynb
trying URL 'https://cran.r-project.org/src/contrib/calibrate_1.7.7.tar.gz'
Content type 'application/x-gzip' length 306782 bytes (299 KB)
==================================================
downloaded 299 KB

trying URL 'https://cran.r-project.org/src/contrib/qqman_0.1.9.tar.gz'
Content type 'application/x-gzip' length 1337980 bytes (1.3 MB)
==================================================
downloaded 1.3 MB

* installing *source* package ‘calibrate’ ...
** package ‘calibrate’ successfully unpacked and MD5 sums checked
** using staged installation
** R
** data
** inst
** byte-compile and prepare package for lazy loading
** help
*** installing help indices
** building package indices
** installing vignettes
** testing if installed package can be loaded from temporary location
** testing if installed package can be loaded from final location
** testing if installed package keeps a record of temporary installation path
* DONE (calibrate)
* installing *source* package ‘qqman’ ...
** package ‘qqman’ successfully unpacked and MD5 sums checked
** using staged installation
** R
** data
*** moving datasets to lazyload DB
** inst
** byte-compile and prepare package for lazy loading
** help
*** installing help indices
** building package indices
** installing vignettes
** testing if installed package can be loaded from temporary location
** testing if installed package can be loaded from final location
** testing if installed package keeps a record of temporary installation path
* DONE (qqman)

The downloaded source packages are in
	‘/tmp/RtmpEjs9db/downloaded_packages’
[I 2024-06-28 11:08:40.453 ServerApp] Saving file at /scripts/19_plot.ipynb
[I 2024-06-28 11:14:40.979 ServerApp] Saving file at /scripts/19_plot.ipynb
[I 2024-06-28 11:16:48.269 ServerApp] Saving file at /scripts/19_plot.ipynb
[I 2024-06-28 11:18:49.147 ServerApp] Saving file at /scripts/19_plot.ipynb
[I 2024-06-28 11:20:49.702 ServerApp] Saving file at /scripts/19_plot.ipynb
[I 2024-06-28 11:22:50.274 ServerApp] Saving file at /scripts/19_plot.ipynb
[I 2024-06-28 11:24:51.022 ServerApp] Saving file at /scripts/19_plot.ipynb
[I 2024-06-28 11:28:51.657 ServerApp] Saving file at /scripts/19_plot.ipynb
[I 2024-06-28 11:29:29.208 ServerApp] Kernel interrupted: a26eb996-c01a-4b50-a73c-399030bd4afd
[I 2024-06-28 11:29:29.399 ServerApp] Kernel interrupted: a26eb996-c01a-4b50-a73c-399030bd4afd
[I 2024-06-28 11:30:52.104 ServerApp] Saving file at /scripts/19_plot.ipynb
[I 2024-06-28 11:32:56.804 ServerApp] Saving file at /scripts/19_plot.ipynb
[I 2024-06-28 11:34:57.266 ServerApp] Saving file at /scripts/19_plot.ipynb
[I 2024-06-28 11:36:57.810 ServerApp] Saving file at /scripts/19_plot.ipynb
[I 2024-06-28 11:38:58.242 ServerApp] Saving file at /scripts/19_plot.ipynb
[I 2024-06-28 11:40:58.714 ServerApp] Saving file at /scripts/19_plot.ipynb
[I 2024-06-28 11:42:59.562 ServerApp] Saving file at /scripts/19_plot.ipynb
[I 2024-06-28 11:45:00.075 ServerApp] Saving file at /scripts/19_plot.ipynb
[I 2024-06-28 11:47:00.753 ServerApp] Saving file at /scripts/19_plot.ipynb
[I 2024-06-28 11:49:01.278 ServerApp] Saving file at /scripts/19_plot.ipynb
[I 2024-06-28 11:51:02.057 ServerApp] Saving file at /scripts/19_plot.ipynb
[I 2024-06-28 11:53:02.729 ServerApp] Saving file at /scripts/19_plot.ipynb
[I 2024-06-28 11:55:03.402 ServerApp] Saving file at /scripts/19_plot.ipynb
[I 2024-06-28 11:55:11.512 ServerApp] Kernel restarted: a26eb996-c01a-4b50-a73c-399030bd4afd
[I 2024-06-28 11:55:11.600 ServerApp] Starting buffering for a26eb996-c01a-4b50-a73c-399030bd4afd:259fe5f2-e55b-426e-aae4-f95c0cafb0c7
[I 2024-06-28 11:55:11.739 ServerApp] Connecting to kernel a26eb996-c01a-4b50-a73c-399030bd4afd.
[I 2024-06-28 11:55:11.739 ServerApp] Restoring connection for a26eb996-c01a-4b50-a73c-399030bd4afd:259fe5f2-e55b-426e-aae4-f95c0cafb0c7
[I 2024-06-28 11:57:04.011 ServerApp] Saving file at /scripts/19_plot.ipynb
trying URL 'https://cran.r-project.org/src/contrib/qqman_0.1.9.tar.gz'
Content type 'application/x-gzip' length 1337980 bytes (1.3 MB)
==================================================
downloaded 1.3 MB

* installing *source* package ‘qqman’ ...
** package ‘qqman’ successfully unpacked and MD5 sums checked
** using staged installation
** R
** data
*** moving datasets to lazyload DB
** inst
** byte-compile and prepare package for lazy loading
** help
*** installing help indices
** building package indices
** installing vignettes
** testing if installed package can be loaded from temporary location
** testing if installed package can be loaded from final location
** testing if installed package keeps a record of temporary installation path
* DONE (qqman)

The downloaded source packages are in
	‘/tmp/Rtmp7tPS94/downloaded_packages’
[I 2024-06-28 12:03:04.697 ServerApp] Saving file at /scripts/19_plot.ipynb
[I 2024-06-28 12:05:05.319 ServerApp] Saving file at /scripts/19_plot.ipynb
trying URL 'https://cran.r-project.org/src/contrib/CMplot_4.5.1.tar.gz'
Content type 'application/x-gzip' length 1763453 bytes (1.7 MB)
==================================================
downloaded 1.7 MB

* installing *source* package ‘CMplot’ ...
** package ‘CMplot’ successfully unpacked and MD5 sums checked
** using staged installation
** R
** data
** byte-compile and prepare package for lazy loading
** help
*** installing help indices
** building package indices
** testing if installed package can be loaded from temporary location
** testing if installed package can be loaded from final location
** testing if installed package keeps a record of temporary installation path
* DONE (CMplot)

The downloaded source packages are in
	‘/tmp/Rtmp7tPS94/downloaded_packages’
[I 2024-06-28 12:07:06.050 ServerApp] Saving file at /scripts/19_plot.ipynb
[I 2024-06-28 12:07:51.186 ServerApp] Starting buffering for a26eb996-c01a-4b50-a73c-399030bd4afd:259fe5f2-e55b-426e-aae4-f95c0cafb0c7
[I 2024-06-28 12:12:53.115 ServerApp] 302 GET / (@127.0.0.1) 0.35ms
[W 2024-06-28 12:12:56.182 LabApp] Could not determine jupyterlab build status without nodejs
[I 2024-06-28 12:12:56.257 ServerApp] Connecting to kernel a26eb996-c01a-4b50-a73c-399030bd4afd.
[I 2024-06-28 12:12:56.443 ServerApp] Starting buffering for a26eb996-c01a-4b50-a73c-399030bd4afd:d6668ba6-654d-4ff3-9b72-2681e0bab3da
[W 2024-06-28 12:12:57.723 ServerApp] Notebook scripts/Untitled1.ipynb is not trusted
[I 2024-06-28 12:12:58.945 ServerApp] Kernel started: 5553585d-6f22-42ee-9fec-ec95129a4c74
[I 2024-06-28 12:12:58.946 ServerApp] Kernel started: 3de7b1a8-6ed6-437b-96df-92b4c7d21f61
[I 2024-06-28 12:12:58.950 ServerApp] Kernel started: 22dbbae0-0dbf-4b2c-97e7-e9a2d376c1f2
[I 2024-06-28 12:12:58.950 ServerApp] Kernel started: aefd246a-5f93-4935-a8c2-277c9aa2c1a9
[I 2024-06-28 12:12:58.957 ServerApp] Kernel started: 7602a5f8-479b-41b1-b005-4cc10a1b6f27
[I 2024-06-28 12:12:59.007 ServerApp] Connecting to kernel a26eb996-c01a-4b50-a73c-399030bd4afd.
[I 2024-06-28 12:12:59.021 ServerApp] Kernel started: c599d78b-ce3b-4556-a788-8fdf25f80766
[I 2024-06-28 12:12:59.562 ServerApp] Connecting to kernel 3de7b1a8-6ed6-437b-96df-92b4c7d21f61.
[I 2024-06-28 12:12:59.584 ServerApp] Connecting to kernel 22dbbae0-0dbf-4b2c-97e7-e9a2d376c1f2.
[I 2024-06-28 12:12:59.628 ServerApp] Connecting to kernel c599d78b-ce3b-4556-a788-8fdf25f80766.
[I 2024-06-28 12:12:59.679 ServerApp] Connecting to kernel 7602a5f8-479b-41b1-b005-4cc10a1b6f27.
[I 2024-06-28 12:12:59.681 ServerApp] Connecting to kernel aefd246a-5f93-4935-a8c2-277c9aa2c1a9.
0.00s - Debugger warning: It seems that frozen modules are being used, which may
0.00s - make the debugger miss breakpoints. Please pass -Xfrozen_modules=off
0.00s - to python to disable frozen modules.
0.00s - Note: Debugging will proceed. Set PYDEVD_DISABLE_FILE_VALIDATION=1 to disable this validation.
[I 2024-06-28 12:13:00.155 ServerApp] Connecting to kernel 5553585d-6f22-42ee-9fec-ec95129a4c74.
[I 2024-06-28 12:13:02.756 ServerApp] Kernel started: 4cf2e7d9-90a9-4627-9fc7-2611654c4e30
[I 2024-06-28 12:13:03.396 ServerApp] Connecting to kernel 4cf2e7d9-90a9-4627-9fc7-2611654c4e30.
[I 2024-06-28 12:14:57.754 ServerApp] Saving file at /scripts/trash.ipynb
[I 2024-06-28 12:15:17.508 ServerApp] Saving file at /scripts/19_plot.ipynb
[I 2024-06-28 12:18:35.144 ServerApp] Saving file at /scripts/19_plot.ipynb
[I 2024-06-28 12:21:04.555 ServerApp] Saving file at /scripts/19_plot.ipynb
[I 2024-06-28 12:23:05.732 ServerApp] Saving file at /scripts/19_plot.ipynb
[I 2024-06-28 12:25:06.258 ServerApp] Saving file at /scripts/19_plot.ipynb
[I 2024-06-28 12:27:11.045 ServerApp] Saving file at /scripts/19_plot.ipynb
[I 2024-06-28 12:27:58.172 ServerApp] Kernel restarted: a26eb996-c01a-4b50-a73c-399030bd4afd
[I 2024-06-28 12:27:58.300 ServerApp] Starting buffering for a26eb996-c01a-4b50-a73c-399030bd4afd:faed2df7-38f0-4694-94a9-d7b0ca293232
[I 2024-06-28 12:27:58.433 ServerApp] Connecting to kernel a26eb996-c01a-4b50-a73c-399030bd4afd.
[I 2024-06-28 12:27:58.433 ServerApp] Restoring connection for a26eb996-c01a-4b50-a73c-399030bd4afd:faed2df7-38f0-4694-94a9-d7b0ca293232
[I 2024-06-28 12:29:11.910 ServerApp] Saving file at /scripts/19_plot.ipynb
trying URL 'https://cran.r-project.org/src/contrib/qqman_0.1.9.tar.gz'
Content type 'application/x-gzip' length 1337980 bytes (1.3 MB)
==================================================
downloaded 1.3 MB

* installing *source* package ‘qqman’ ...
** package ‘qqman’ successfully unpacked and MD5 sums checked
** using staged installation
** R
** data
*** moving datasets to lazyload DB
** inst
** byte-compile and prepare package for lazy loading
** help
*** installing help indices
** building package indices
** installing vignettes
** testing if installed package can be loaded from temporary location
** testing if installed package can be loaded from final location
** testing if installed package keeps a record of temporary installation path
* DONE (qqman)

The downloaded source packages are in
	‘/tmp/RtmpCgfzUu/downloaded_packages’
[I 2024-06-28 12:37:20.635 ServerApp] Saving file at /scripts/19_plot.ipynb
[I 2024-06-28 12:39:21.370 ServerApp] Saving file at /scripts/19_plot.ipynb
[I 2024-06-28 12:41:21.959 ServerApp] Saving file at /scripts/19_plot.ipynb
[I 2024-06-28 12:46:23.455 ServerApp] Starting buffering for 22dbbae0-0dbf-4b2c-97e7-e9a2d376c1f2:c95f4f8e-20b9-4963-a49d-7e33b3b14f79
[I 2024-06-28 12:46:23.456 ServerApp] Starting buffering for 4cf2e7d9-90a9-4627-9fc7-2611654c4e30:e8dc3f20-4f09-432e-9ab3-b1c6b1eeedb4
[I 2024-06-28 12:46:23.456 ServerApp] Starting buffering for 5553585d-6f22-42ee-9fec-ec95129a4c74:3a3bd343-59ce-4581-a6ed-916ac3f95944
[I 2024-06-28 12:46:23.456 ServerApp] Starting buffering for 3de7b1a8-6ed6-437b-96df-92b4c7d21f61:d370747a-9762-459a-a332-44b0a0860447
[I 2024-06-28 12:46:23.457 ServerApp] Starting buffering for 7602a5f8-479b-41b1-b005-4cc10a1b6f27:90668f02-4bfd-4bcf-a6ab-11be2ce5a207
[I 2024-06-28 12:46:23.457 ServerApp] Starting buffering for aefd246a-5f93-4935-a8c2-277c9aa2c1a9:a7215279-c2a3-4863-8acb-025b5d7f1af1
[I 2024-06-28 12:46:23.457 ServerApp] Starting buffering for c599d78b-ce3b-4556-a788-8fdf25f80766:466985d9-a054-4320-8b44-6da43f520e45
[I 2024-06-28 12:46:23.457 ServerApp] Starting buffering for a26eb996-c01a-4b50-a73c-399030bd4afd:faed2df7-38f0-4694-94a9-d7b0ca293232
slurmstepd: error: *** JOB 31694041 ON exp-6-45 CANCELLED AT 2024-06-28T18:52:58 DUE TO TIME LIMIT ***
[C 2024-06-28 18:52:58.865 ServerApp] received signal 15, stopping
[I 2024-06-28 18:52:58.896 ServerApp] Shutting down 5 extensions
[I 2024-06-28 18:52:58.897 ServerApp] Shutting down 8 kernels
[I 2024-06-28 18:52:58.897 ServerApp] Kernel shutdown: aefd246a-5f93-4935-a8c2-277c9aa2c1a9
[I 2024-06-28 18:52:58.898 ServerApp] Kernel shutdown: a26eb996-c01a-4b50-a73c-399030bd4afd
[I 2024-06-28 18:52:58.898 ServerApp] Kernel shutdown: c599d78b-ce3b-4556-a788-8fdf25f80766
[I 2024-06-28 18:52:58.898 ServerApp] Kernel shutdown: 4cf2e7d9-90a9-4627-9fc7-2611654c4e30
[I 2024-06-28 18:52:58.898 ServerApp] Kernel shutdown: 7602a5f8-479b-41b1-b005-4cc10a1b6f27
[I 2024-06-28 18:52:58.899 ServerApp] Kernel shutdown: 22dbbae0-0dbf-4b2c-97e7-e9a2d376c1f2
[I 2024-06-28 18:52:58.899 ServerApp] Kernel shutdown: 3de7b1a8-6ed6-437b-96df-92b4c7d21f61
[I 2024-06-28 18:52:58.899 ServerApp] Kernel shutdown: 5553585d-6f22-42ee-9fec-ec95129a4c74
